INFO 2022-04-25 12:21:52,882 autoreload 18665 139932068738880 Watching for file changes with StatReloader
WARNING 2022-04-25 12:21:54,236 log 18665 139931991398144 Not Found: /
WARNING 2022-04-25 12:21:54,236 basehttp 18665 139931991398144 "GET / HTTP/1.1" 404 2967
INFO 2022-04-25 12:21:59,599 views 18665 139931991398144 List of mailboxes load successfully
INFO 2022-04-25 12:21:59,626 basehttp 18665 139931991398144 "GET /api/mailbox/ HTTP/1.1" 200 6868
INFO 2022-04-26 13:08:49,230 autoreload 21716 140042458265408 Watching for file changes with StatReloader
WARNING 2022-04-26 13:08:50,675 log 21716 140042307630848 Not Found: /
WARNING 2022-04-26 13:08:50,676 basehttp 21716 140042307630848 "GET / HTTP/1.1" 404 2967
WARNING 2022-04-26 13:08:51,334 log 21716 140042307630848 Not Found: /favicon.ico
WARNING 2022-04-26 13:08:51,334 basehttp 21716 140042307630848 "GET /favicon.ico HTTP/1.1" 404 3018
INFO 2022-04-26 13:08:54,373 views 21716 140042307630848 List of mailboxes load successfully
ERROR 2022-04-26 13:08:54,427 log 21716 140042307630848 Internal Server Error: /api/mailbox/
Traceback (most recent call last):
  File "/home/matt/.local/lib/python3.8/site-packages/django/db/backends/utils.py", line 85, in _execute
    return self.cursor.execute(sql, params)
psycopg2.errors.UndefinedColumn: column BASE_mailbox.is_active does not exist
LINE 1: ..._mailbox"."email_from", "BASE_mailbox"."use_ssl", "BASE_mail...
                                                             ^


The above exception was the direct cause of the following exception:

Traceback (most recent call last):
  File "/home/matt/.local/lib/python3.8/site-packages/django/core/handlers/exception.py", line 47, in inner
    response = get_response(request)
  File "/home/matt/.local/lib/python3.8/site-packages/django/core/handlers/base.py", line 181, in _get_response
    response = wrapped_callback(request, *callback_args, **callback_kwargs)
  File "/home/matt/.local/lib/python3.8/site-packages/django/views/decorators/csrf.py", line 54, in wrapped_view
    return view_func(*args, **kwargs)
  File "/home/matt/.local/lib/python3.8/site-packages/django/views/generic/base.py", line 69, in view
    return self.dispatch(request, *args, **kwargs)
  File "/usr/local/lib/python3.8/dist-packages/rest_framework/views.py", line 509, in dispatch
    response = self.handle_exception(exc)
  File "/usr/local/lib/python3.8/dist-packages/rest_framework/views.py", line 469, in handle_exception
    self.raise_uncaught_exception(exc)
  File "/usr/local/lib/python3.8/dist-packages/rest_framework/views.py", line 480, in raise_uncaught_exception
    raise exc
  File "/usr/local/lib/python3.8/dist-packages/rest_framework/views.py", line 506, in dispatch
    response = handler(request, *args, **kwargs)
  File "/usr/local/lib/python3.8/dist-packages/rest_framework/decorators.py", line 50, in handler
    return func(*args, **kwargs)
  File "/home/matt/PycharmProjects/mailAPI/BASE/views.py", line 17, in manage_mailboxes
    return Response(serializer.data)
  File "/usr/local/lib/python3.8/dist-packages/rest_framework/serializers.py", line 768, in data
    ret = super().data
  File "/usr/local/lib/python3.8/dist-packages/rest_framework/serializers.py", line 253, in data
    self._data = self.to_representation(self.instance)
  File "/usr/local/lib/python3.8/dist-packages/rest_framework/serializers.py", line 686, in to_representation
    return [
  File "/home/matt/.local/lib/python3.8/site-packages/django/db/models/query.py", line 280, in __iter__
    self._fetch_all()
  File "/home/matt/.local/lib/python3.8/site-packages/django/db/models/query.py", line 1354, in _fetch_all
    self._result_cache = list(self._iterable_class(self))
  File "/home/matt/.local/lib/python3.8/site-packages/django/db/models/query.py", line 51, in __iter__
    results = compiler.execute_sql(chunked_fetch=self.chunked_fetch, chunk_size=self.chunk_size)
  File "/home/matt/.local/lib/python3.8/site-packages/django/db/models/sql/compiler.py", line 1202, in execute_sql
    cursor.execute(sql, params)
  File "/home/matt/.local/lib/python3.8/site-packages/django/db/backends/utils.py", line 99, in execute
    return super().execute(sql, params)
  File "/home/matt/.local/lib/python3.8/site-packages/django/db/backends/utils.py", line 67, in execute
    return self._execute_with_wrappers(sql, params, many=False, executor=self._execute)
  File "/home/matt/.local/lib/python3.8/site-packages/django/db/backends/utils.py", line 76, in _execute_with_wrappers
    return executor(sql, params, many, context)
  File "/home/matt/.local/lib/python3.8/site-packages/django/db/backends/utils.py", line 85, in _execute
    return self.cursor.execute(sql, params)
  File "/home/matt/.local/lib/python3.8/site-packages/django/db/utils.py", line 90, in __exit__
    raise dj_exc_value.with_traceback(traceback) from exc_value
  File "/home/matt/.local/lib/python3.8/site-packages/django/db/backends/utils.py", line 85, in _execute
    return self.cursor.execute(sql, params)
django.db.utils.ProgrammingError: column BASE_mailbox.is_active does not exist
LINE 1: ..._mailbox"."email_from", "BASE_mailbox"."use_ssl", "BASE_mail...
                                                             ^

ERROR 2022-04-26 13:08:54,429 basehttp 21716 140042307630848 "GET /api/mailbox/ HTTP/1.1" 500 167825
INFO 2022-04-26 13:09:40,437 autoreload 21914 139637853714240 Watching for file changes with StatReloader
WARNING 2022-04-26 13:09:41,627 log 21914 139637708289792 Not Found: /
WARNING 2022-04-26 13:09:41,627 basehttp 21914 139637708289792 "GET / HTTP/1.1" 404 2967
INFO 2022-04-26 13:09:47,252 views 21914 139637708289792 List of mailboxes load successfully
ERROR 2022-04-26 13:09:47,301 log 21914 139637708289792 Internal Server Error: /api/mailbox/
Traceback (most recent call last):
  File "/home/matt/.local/lib/python3.8/site-packages/django/db/backends/utils.py", line 85, in _execute
    return self.cursor.execute(sql, params)
psycopg2.errors.UndefinedColumn: column BASE_mailbox.is_active does not exist
LINE 1: ..._mailbox"."email_from", "BASE_mailbox"."use_ssl", "BASE_mail...
                                                             ^


The above exception was the direct cause of the following exception:

Traceback (most recent call last):
  File "/home/matt/.local/lib/python3.8/site-packages/django/core/handlers/exception.py", line 47, in inner
    response = get_response(request)
  File "/home/matt/.local/lib/python3.8/site-packages/django/core/handlers/base.py", line 181, in _get_response
    response = wrapped_callback(request, *callback_args, **callback_kwargs)
  File "/home/matt/.local/lib/python3.8/site-packages/django/views/decorators/csrf.py", line 54, in wrapped_view
    return view_func(*args, **kwargs)
  File "/home/matt/.local/lib/python3.8/site-packages/django/views/generic/base.py", line 69, in view
    return self.dispatch(request, *args, **kwargs)
  File "/usr/local/lib/python3.8/dist-packages/rest_framework/views.py", line 509, in dispatch
    response = self.handle_exception(exc)
  File "/usr/local/lib/python3.8/dist-packages/rest_framework/views.py", line 469, in handle_exception
    self.raise_uncaught_exception(exc)
  File "/usr/local/lib/python3.8/dist-packages/rest_framework/views.py", line 480, in raise_uncaught_exception
    raise exc
  File "/usr/local/lib/python3.8/dist-packages/rest_framework/views.py", line 506, in dispatch
    response = handler(request, *args, **kwargs)
  File "/usr/local/lib/python3.8/dist-packages/rest_framework/decorators.py", line 50, in handler
    return func(*args, **kwargs)
  File "/home/matt/PycharmProjects/mailAPI/BASE/views.py", line 17, in manage_mailboxes
    return Response(serializer.data)
  File "/usr/local/lib/python3.8/dist-packages/rest_framework/serializers.py", line 768, in data
    ret = super().data
  File "/usr/local/lib/python3.8/dist-packages/rest_framework/serializers.py", line 253, in data
    self._data = self.to_representation(self.instance)
  File "/usr/local/lib/python3.8/dist-packages/rest_framework/serializers.py", line 686, in to_representation
    return [
  File "/home/matt/.local/lib/python3.8/site-packages/django/db/models/query.py", line 280, in __iter__
    self._fetch_all()
  File "/home/matt/.local/lib/python3.8/site-packages/django/db/models/query.py", line 1354, in _fetch_all
    self._result_cache = list(self._iterable_class(self))
  File "/home/matt/.local/lib/python3.8/site-packages/django/db/models/query.py", line 51, in __iter__
    results = compiler.execute_sql(chunked_fetch=self.chunked_fetch, chunk_size=self.chunk_size)
  File "/home/matt/.local/lib/python3.8/site-packages/django/db/models/sql/compiler.py", line 1202, in execute_sql
    cursor.execute(sql, params)
  File "/home/matt/.local/lib/python3.8/site-packages/django/db/backends/utils.py", line 99, in execute
    return super().execute(sql, params)
  File "/home/matt/.local/lib/python3.8/site-packages/django/db/backends/utils.py", line 67, in execute
    return self._execute_with_wrappers(sql, params, many=False, executor=self._execute)
  File "/home/matt/.local/lib/python3.8/site-packages/django/db/backends/utils.py", line 76, in _execute_with_wrappers
    return executor(sql, params, many, context)
  File "/home/matt/.local/lib/python3.8/site-packages/django/db/backends/utils.py", line 85, in _execute
    return self.cursor.execute(sql, params)
  File "/home/matt/.local/lib/python3.8/site-packages/django/db/utils.py", line 90, in __exit__
    raise dj_exc_value.with_traceback(traceback) from exc_value
  File "/home/matt/.local/lib/python3.8/site-packages/django/db/backends/utils.py", line 85, in _execute
    return self.cursor.execute(sql, params)
django.db.utils.ProgrammingError: column BASE_mailbox.is_active does not exist
LINE 1: ..._mailbox"."email_from", "BASE_mailbox"."use_ssl", "BASE_mail...
                                                             ^

ERROR 2022-04-26 13:09:47,302 basehttp 21914 139637708289792 "GET /api/mailbox/ HTTP/1.1" 500 167825
WARNING 2022-04-26 13:12:02,504 log 21914 139637708289792 Not Found: /
WARNING 2022-04-26 13:12:02,504 basehttp 21914 139637708289792 "GET / HTTP/1.1" 404 2967
INFO 2022-04-26 13:12:41,553 autoreload 22316 140089179559744 Watching for file changes with StatReloader
WARNING 2022-04-26 13:12:43,271 log 22316 140089101694720 Not Found: /
WARNING 2022-04-26 13:12:43,272 basehttp 22316 140089101694720 "GET / HTTP/1.1" 404 2967
INFO 2022-04-26 13:12:48,740 views 22316 140089101694720 List of mailboxes load successfully
ERROR 2022-04-26 13:12:48,800 log 22316 140089101694720 Internal Server Error: /api/mailbox/
Traceback (most recent call last):
  File "/home/matt/.local/lib/python3.8/site-packages/django/db/backends/utils.py", line 85, in _execute
    return self.cursor.execute(sql, params)
psycopg2.errors.UndefinedColumn: column BASE_mailbox.is_active does not exist
LINE 1: ..._mailbox"."email_from", "BASE_mailbox"."use_ssl", "BASE_mail...
                                                             ^


The above exception was the direct cause of the following exception:

Traceback (most recent call last):
  File "/home/matt/.local/lib/python3.8/site-packages/django/core/handlers/exception.py", line 47, in inner
    response = get_response(request)
  File "/home/matt/.local/lib/python3.8/site-packages/django/core/handlers/base.py", line 181, in _get_response
    response = wrapped_callback(request, *callback_args, **callback_kwargs)
  File "/home/matt/.local/lib/python3.8/site-packages/django/views/decorators/csrf.py", line 54, in wrapped_view
    return view_func(*args, **kwargs)
  File "/home/matt/.local/lib/python3.8/site-packages/django/views/generic/base.py", line 69, in view
    return self.dispatch(request, *args, **kwargs)
  File "/usr/local/lib/python3.8/dist-packages/rest_framework/views.py", line 509, in dispatch
    response = self.handle_exception(exc)
  File "/usr/local/lib/python3.8/dist-packages/rest_framework/views.py", line 469, in handle_exception
    self.raise_uncaught_exception(exc)
  File "/usr/local/lib/python3.8/dist-packages/rest_framework/views.py", line 480, in raise_uncaught_exception
    raise exc
  File "/usr/local/lib/python3.8/dist-packages/rest_framework/views.py", line 506, in dispatch
    response = handler(request, *args, **kwargs)
  File "/usr/local/lib/python3.8/dist-packages/rest_framework/decorators.py", line 50, in handler
    return func(*args, **kwargs)
  File "/home/matt/PycharmProjects/mailAPI/BASE/views.py", line 17, in manage_mailboxes
    return Response(serializer.data)
  File "/usr/local/lib/python3.8/dist-packages/rest_framework/serializers.py", line 768, in data
    ret = super().data
  File "/usr/local/lib/python3.8/dist-packages/rest_framework/serializers.py", line 253, in data
    self._data = self.to_representation(self.instance)
  File "/usr/local/lib/python3.8/dist-packages/rest_framework/serializers.py", line 686, in to_representation
    return [
  File "/home/matt/.local/lib/python3.8/site-packages/django/db/models/query.py", line 280, in __iter__
    self._fetch_all()
  File "/home/matt/.local/lib/python3.8/site-packages/django/db/models/query.py", line 1354, in _fetch_all
    self._result_cache = list(self._iterable_class(self))
  File "/home/matt/.local/lib/python3.8/site-packages/django/db/models/query.py", line 51, in __iter__
    results = compiler.execute_sql(chunked_fetch=self.chunked_fetch, chunk_size=self.chunk_size)
  File "/home/matt/.local/lib/python3.8/site-packages/django/db/models/sql/compiler.py", line 1202, in execute_sql
    cursor.execute(sql, params)
  File "/home/matt/.local/lib/python3.8/site-packages/django/db/backends/utils.py", line 99, in execute
    return super().execute(sql, params)
  File "/home/matt/.local/lib/python3.8/site-packages/django/db/backends/utils.py", line 67, in execute
    return self._execute_with_wrappers(sql, params, many=False, executor=self._execute)
  File "/home/matt/.local/lib/python3.8/site-packages/django/db/backends/utils.py", line 76, in _execute_with_wrappers
    return executor(sql, params, many, context)
  File "/home/matt/.local/lib/python3.8/site-packages/django/db/backends/utils.py", line 85, in _execute
    return self.cursor.execute(sql, params)
  File "/home/matt/.local/lib/python3.8/site-packages/django/db/utils.py", line 90, in __exit__
    raise dj_exc_value.with_traceback(traceback) from exc_value
  File "/home/matt/.local/lib/python3.8/site-packages/django/db/backends/utils.py", line 85, in _execute
    return self.cursor.execute(sql, params)
django.db.utils.ProgrammingError: column BASE_mailbox.is_active does not exist
LINE 1: ..._mailbox"."email_from", "BASE_mailbox"."use_ssl", "BASE_mail...
                                                             ^

ERROR 2022-04-26 13:12:48,801 basehttp 22316 140089101694720 "GET /api/mailbox/ HTTP/1.1" 500 167825
INFO 2022-04-26 13:20:55,805 basehttp 22316 140089101694720 "GET /admin HTTP/1.1" 301 0
INFO 2022-04-26 13:20:55,822 basehttp 22316 140089101694720 "GET /admin/ HTTP/1.1" 302 0
INFO 2022-04-26 13:20:55,849 basehttp 22316 140089101694720 "GET /admin/login/?next=/admin/ HTTP/1.1" 200 2215
INFO 2022-04-26 13:20:55,874 basehttp 22316 140089093302016 "GET /static/admin/css/nav_sidebar.css HTTP/1.1" 200 2616
INFO 2022-04-26 13:20:55,875 basehttp 22316 140088881182464 "GET /static/admin/css/login.css HTTP/1.1" 200 954
INFO 2022-04-26 13:20:55,876 basehttp 22316 140089101694720 "GET /static/admin/css/base.css HTTP/1.1" 200 19513
INFO 2022-04-26 13:20:55,876 basehttp 22316 140088872789760 "GET /static/admin/css/responsive.css HTTP/1.1" 200 18545
INFO 2022-04-26 13:20:56,346 basehttp 22316 140089101694720 "GET /static/admin/js/nav_sidebar.js HTTP/1.1" 200 3401
INFO 2022-04-26 13:20:56,347 basehttp 22316 140088872789760 "GET /static/admin/css/fonts.css HTTP/1.1" 200 423
INFO 2022-04-26 13:20:56,491 basehttp 22316 140089101694720 "GET /static/admin/fonts/Roboto-Regular-webfont.woff HTTP/1.1" 200 85876
INFO 2022-04-26 13:20:56,492 basehttp 22316 140088872789760 "GET /static/admin/fonts/Roboto-Light-webfont.woff HTTP/1.1" 200 85692
INFO 2022-04-26 13:22:05,940 autoreload 22938 140349516900160 Watching for file changes with StatReloader
WARNING 2022-04-26 13:22:07,146 log 22938 140349439559424 Not Found: /
WARNING 2022-04-26 13:22:07,146 basehttp 22938 140349439559424 "GET / HTTP/1.1" 404 2967
INFO 2022-04-26 13:22:10,968 basehttp 22938 140349439559424 "GET /admin/ HTTP/1.1" 302 0
INFO 2022-04-26 13:22:10,989 basehttp 22938 140349439559424 "GET /admin/login/?next=/admin/ HTTP/1.1" 200 2215
INFO 2022-04-26 13:22:16,298 basehttp 22938 140349439559424 "POST /admin/login/?next=/admin/ HTTP/1.1" 302 0
INFO 2022-04-26 13:22:16,332 basehttp 22938 140349439559424 "GET /admin/ HTTP/1.1" 200 4799
INFO 2022-04-26 13:22:16,351 basehttp 22938 140349439559424 "GET /static/admin/css/dashboard.css HTTP/1.1" 200 380
INFO 2022-04-26 13:22:16,487 basehttp 22938 140349439559424 "GET /static/admin/img/icon-addlink.svg HTTP/1.1" 200 331
INFO 2022-04-26 13:22:16,488 basehttp 22938 140349431166720 "GET /static/admin/img/icon-changelink.svg HTTP/1.1" 200 380
INFO 2022-04-26 13:22:16,552 basehttp 22938 140349431166720 "GET /static/admin/fonts/Roboto-Bold-webfont.woff HTTP/1.1" 200 86184
ERROR 2022-04-26 13:22:18,856 log 22938 140349431166720 Internal Server Error: /admin/BASE/email/
Traceback (most recent call last):
  File "/home/matt/.local/lib/python3.8/site-packages/django/db/backends/utils.py", line 85, in _execute
    return self.cursor.execute(sql, params)
psycopg2.errors.UndefinedColumn: column BASE_email.cc does not exist
LINE 1: ...", "BASE_email"."template_id", "BASE_email"."to", "BASE_emai...
                                                             ^


The above exception was the direct cause of the following exception:

Traceback (most recent call last):
  File "/home/matt/.local/lib/python3.8/site-packages/django/core/handlers/exception.py", line 47, in inner
    response = get_response(request)
  File "/home/matt/.local/lib/python3.8/site-packages/django/core/handlers/base.py", line 181, in _get_response
    response = wrapped_callback(request, *callback_args, **callback_kwargs)
  File "/home/matt/.local/lib/python3.8/site-packages/django/contrib/admin/options.py", line 622, in wrapper
    return self.admin_site.admin_view(view)(*args, **kwargs)
  File "/home/matt/.local/lib/python3.8/site-packages/django/utils/decorators.py", line 130, in _wrapped_view
    response = view_func(request, *args, **kwargs)
  File "/home/matt/.local/lib/python3.8/site-packages/django/views/decorators/cache.py", line 56, in _wrapped_view_func
    response = view_func(request, *args, **kwargs)
  File "/home/matt/.local/lib/python3.8/site-packages/django/contrib/admin/sites.py", line 236, in inner
    return view(request, *args, **kwargs)
  File "/home/matt/.local/lib/python3.8/site-packages/django/utils/decorators.py", line 43, in _wrapper
    return bound_method(*args, **kwargs)
  File "/home/matt/.local/lib/python3.8/site-packages/django/utils/decorators.py", line 130, in _wrapped_view
    response = view_func(request, *args, **kwargs)
  File "/home/matt/.local/lib/python3.8/site-packages/django/contrib/admin/options.py", line 1828, in changelist_view
    'selection_note': _('0 of %(cnt)s selected') % {'cnt': len(cl.result_list)},
  File "/home/matt/.local/lib/python3.8/site-packages/django/db/models/query.py", line 262, in __len__
    self._fetch_all()
  File "/home/matt/.local/lib/python3.8/site-packages/django/db/models/query.py", line 1354, in _fetch_all
    self._result_cache = list(self._iterable_class(self))
  File "/home/matt/.local/lib/python3.8/site-packages/django/db/models/query.py", line 51, in __iter__
    results = compiler.execute_sql(chunked_fetch=self.chunked_fetch, chunk_size=self.chunk_size)
  File "/home/matt/.local/lib/python3.8/site-packages/django/db/models/sql/compiler.py", line 1202, in execute_sql
    cursor.execute(sql, params)
  File "/home/matt/.local/lib/python3.8/site-packages/django/db/backends/utils.py", line 99, in execute
    return super().execute(sql, params)
  File "/home/matt/.local/lib/python3.8/site-packages/django/db/backends/utils.py", line 67, in execute
    return self._execute_with_wrappers(sql, params, many=False, executor=self._execute)
  File "/home/matt/.local/lib/python3.8/site-packages/django/db/backends/utils.py", line 76, in _execute_with_wrappers
    return executor(sql, params, many, context)
  File "/home/matt/.local/lib/python3.8/site-packages/django/db/backends/utils.py", line 85, in _execute
    return self.cursor.execute(sql, params)
  File "/home/matt/.local/lib/python3.8/site-packages/django/db/utils.py", line 90, in __exit__
    raise dj_exc_value.with_traceback(traceback) from exc_value
  File "/home/matt/.local/lib/python3.8/site-packages/django/db/backends/utils.py", line 85, in _execute
    return self.cursor.execute(sql, params)
django.db.utils.ProgrammingError: column BASE_email.cc does not exist
LINE 1: ...", "BASE_email"."template_id", "BASE_email"."to", "BASE_emai...
                                                             ^

ERROR 2022-04-26 13:22:18,858 basehttp 22938 140349431166720 "GET /admin/BASE/email/ HTTP/1.1" 500 154170
INFO 2022-04-26 13:22:32,557 basehttp 22938 140349431166720 "GET /admin/ HTTP/1.1" 200 4799
INFO 2022-04-26 13:22:33,942 basehttp 22938 140349431166720 "GET /admin/BASE/mailbox/add/ HTTP/1.1" 200 9072
INFO 2022-04-26 13:22:33,976 basehttp 22938 140349431166720 "GET /static/admin/css/forms.css HTTP/1.1" 200 8835
INFO 2022-04-26 13:22:33,978 basehttp 22938 140349411235584 "GET /static/admin/js/jquery.init.js HTTP/1.1" 200 347
INFO 2022-04-26 13:22:33,978 basehttp 22938 140349062248192 "GET /static/admin/js/core.js HTTP/1.1" 200 5698
INFO 2022-04-26 13:22:33,978 basehttp 22938 140349053855488 "GET /static/admin/js/admin/RelatedObjectLookups.js HTTP/1.1" 200 5984
INFO 2022-04-26 13:22:33,981 basehttp 22938 140349419628288 "GET /static/admin/js/vendor/jquery/jquery.js HTTP/1.1" 200 288580
INFO 2022-04-26 13:22:33,987 basehttp 22938 140349439559424 "GET /admin/jsi18n/ HTTP/1.1" 200 3343
INFO 2022-04-26 13:22:33,990 basehttp 22938 140349431166720 "GET /static/admin/js/actions.js HTTP/1.1" 200 7872
INFO 2022-04-26 13:22:33,990 basehttp 22938 140349419628288 "GET /static/admin/js/prepopulate_init.js HTTP/1.1" 200 492
INFO 2022-04-26 13:22:33,990 basehttp 22938 140349411235584 "GET /static/admin/js/urlify.js HTTP/1.1" 200 7902
INFO 2022-04-26 13:22:33,991 basehttp 22938 140349062248192 "GET /static/admin/js/prepopulate.js HTTP/1.1" 200 1531
INFO 2022-04-26 13:22:33,992 basehttp 22938 140349053855488 "GET /static/admin/js/vendor/xregexp/xregexp.js HTTP/1.1" 200 232381
INFO 2022-04-26 13:22:34,082 basehttp 22938 140349053855488 "GET /static/admin/css/widgets.css HTTP/1.1" 200 11097
INFO 2022-04-26 13:22:34,142 basehttp 22938 140349053855488 "GET /static/admin/js/change_form.js HTTP/1.1" 200 606
INFO 2022-04-26 13:22:35,578 basehttp 22938 140349053855488 "GET /admin/ HTTP/1.1" 200 4799
INFO 2022-04-26 13:22:36,889 basehttp 22938 140349053855488 "GET /admin/BASE/template/add/ HTTP/1.1" 200 6338
INFO 2022-04-26 13:22:36,928 basehttp 22938 140349053855488 "GET /admin/jsi18n/ HTTP/1.1" 200 3343
INFO 2022-04-26 13:22:38,406 basehttp 22938 140349053855488 "GET /admin/ HTTP/1.1" 200 4799
ERROR 2022-04-26 13:22:44,313 log 22938 140349053855488 Internal Server Error: /admin/BASE/email/add/
Traceback (most recent call last):
  File "/home/matt/.local/lib/python3.8/site-packages/django/db/backends/utils.py", line 85, in _execute
    return self.cursor.execute(sql, params)
psycopg2.errors.UndefinedColumn: column BASE_mailbox.is_active does not exist
LINE 1: ..._mailbox"."email_from", "BASE_mailbox"."use_ssl", "BASE_mail...
                                                             ^


The above exception was the direct cause of the following exception:

Traceback (most recent call last):
  File "/home/matt/.local/lib/python3.8/site-packages/django/db/models/sql/compiler.py", line 1202, in execute_sql
    cursor.execute(sql, params)
  File "/home/matt/.local/lib/python3.8/site-packages/django/db/backends/utils.py", line 99, in execute
    return super().execute(sql, params)
  File "/home/matt/.local/lib/python3.8/site-packages/django/db/backends/utils.py", line 67, in execute
    return self._execute_with_wrappers(sql, params, many=False, executor=self._execute)
  File "/home/matt/.local/lib/python3.8/site-packages/django/db/backends/utils.py", line 76, in _execute_with_wrappers
    return executor(sql, params, many, context)
  File "/home/matt/.local/lib/python3.8/site-packages/django/db/backends/utils.py", line 85, in _execute
    return self.cursor.execute(sql, params)
  File "/home/matt/.local/lib/python3.8/site-packages/django/db/utils.py", line 90, in __exit__
    raise dj_exc_value.with_traceback(traceback) from exc_value
  File "/home/matt/.local/lib/python3.8/site-packages/django/db/backends/utils.py", line 85, in _execute
    return self.cursor.execute(sql, params)
django.db.utils.ProgrammingError: column BASE_mailbox.is_active does not exist
LINE 1: ..._mailbox"."email_from", "BASE_mailbox"."use_ssl", "BASE_mail...
                                                             ^


During handling of the above exception, another exception occurred:

Traceback (most recent call last):
  File "/home/matt/.local/lib/python3.8/site-packages/django/core/handlers/exception.py", line 47, in inner
    response = get_response(request)
  File "/home/matt/.local/lib/python3.8/site-packages/django/core/handlers/base.py", line 204, in _get_response
    response = response.render()
  File "/home/matt/.local/lib/python3.8/site-packages/django/template/response.py", line 105, in render
    self.content = self.rendered_content
  File "/home/matt/.local/lib/python3.8/site-packages/django/template/response.py", line 83, in rendered_content
    return template.render(context, self._request)
  File "/home/matt/.local/lib/python3.8/site-packages/django/template/backends/django.py", line 61, in render
    return self.template.render(context)
  File "/home/matt/.local/lib/python3.8/site-packages/django/template/base.py", line 176, in render
    return self._render(context)
  File "/home/matt/.local/lib/python3.8/site-packages/django/template/base.py", line 168, in _render
    return self.nodelist.render(context)
  File "/home/matt/.local/lib/python3.8/site-packages/django/template/base.py", line 977, in render
    return SafeString(''.join([
  File "/home/matt/.local/lib/python3.8/site-packages/django/template/base.py", line 978, in <listcomp>
    node.render_annotated(context) for node in self
  File "/home/matt/.local/lib/python3.8/site-packages/django/template/base.py", line 938, in render_annotated
    return self.render(context)
  File "/home/matt/.local/lib/python3.8/site-packages/django/template/loader_tags.py", line 153, in render
    return compiled_parent._render(context)
  File "/home/matt/.local/lib/python3.8/site-packages/django/template/base.py", line 168, in _render
    return self.nodelist.render(context)
  File "/home/matt/.local/lib/python3.8/site-packages/django/template/base.py", line 977, in render
    return SafeString(''.join([
  File "/home/matt/.local/lib/python3.8/site-packages/django/template/base.py", line 978, in <listcomp>
    node.render_annotated(context) for node in self
  File "/home/matt/.local/lib/python3.8/site-packages/django/template/base.py", line 938, in render_annotated
    return self.render(context)
  File "/home/matt/.local/lib/python3.8/site-packages/django/template/loader_tags.py", line 153, in render
    return compiled_parent._render(context)
  File "/home/matt/.local/lib/python3.8/site-packages/django/template/base.py", line 168, in _render
    return self.nodelist.render(context)
  File "/home/matt/.local/lib/python3.8/site-packages/django/template/base.py", line 977, in render
    return SafeString(''.join([
  File "/home/matt/.local/lib/python3.8/site-packages/django/template/base.py", line 978, in <listcomp>
    node.render_annotated(context) for node in self
  File "/home/matt/.local/lib/python3.8/site-packages/django/template/base.py", line 938, in render_annotated
    return self.render(context)
  File "/home/matt/.local/lib/python3.8/site-packages/django/template/loader_tags.py", line 65, in render
    result = block.nodelist.render(context)
  File "/home/matt/.local/lib/python3.8/site-packages/django/template/base.py", line 977, in render
    return SafeString(''.join([
  File "/home/matt/.local/lib/python3.8/site-packages/django/template/base.py", line 978, in <listcomp>
    node.render_annotated(context) for node in self
  File "/home/matt/.local/lib/python3.8/site-packages/django/template/base.py", line 938, in render_annotated
    return self.render(context)
  File "/home/matt/.local/lib/python3.8/site-packages/django/template/loader_tags.py", line 65, in render
    result = block.nodelist.render(context)
  File "/home/matt/.local/lib/python3.8/site-packages/django/template/base.py", line 977, in render
    return SafeString(''.join([
  File "/home/matt/.local/lib/python3.8/site-packages/django/template/base.py", line 978, in <listcomp>
    node.render_annotated(context) for node in self
  File "/home/matt/.local/lib/python3.8/site-packages/django/template/base.py", line 938, in render_annotated
    return self.render(context)
  File "/home/matt/.local/lib/python3.8/site-packages/django/template/defaulttags.py", line 214, in render
    nodelist.append(node.render_annotated(context))
  File "/home/matt/.local/lib/python3.8/site-packages/django/template/base.py", line 938, in render_annotated
    return self.render(context)
  File "/home/matt/.local/lib/python3.8/site-packages/django/template/loader_tags.py", line 201, in render
    return template.render(context)
  File "/home/matt/.local/lib/python3.8/site-packages/django/template/base.py", line 178, in render
    return self._render(context)
  File "/home/matt/.local/lib/python3.8/site-packages/django/template/base.py", line 168, in _render
    return self.nodelist.render(context)
  File "/home/matt/.local/lib/python3.8/site-packages/django/template/base.py", line 977, in render
    return SafeString(''.join([
  File "/home/matt/.local/lib/python3.8/site-packages/django/template/base.py", line 978, in <listcomp>
    node.render_annotated(context) for node in self
  File "/home/matt/.local/lib/python3.8/site-packages/django/template/base.py", line 938, in render_annotated
    return self.render(context)
  File "/home/matt/.local/lib/python3.8/site-packages/django/template/defaulttags.py", line 214, in render
    nodelist.append(node.render_annotated(context))
  File "/home/matt/.local/lib/python3.8/site-packages/django/template/base.py", line 938, in render_annotated
    return self.render(context)
  File "/home/matt/.local/lib/python3.8/site-packages/django/template/defaulttags.py", line 214, in render
    nodelist.append(node.render_annotated(context))
  File "/home/matt/.local/lib/python3.8/site-packages/django/template/base.py", line 938, in render_annotated
    return self.render(context)
  File "/home/matt/.local/lib/python3.8/site-packages/django/template/defaulttags.py", line 295, in render
    return nodelist.render(context)
  File "/home/matt/.local/lib/python3.8/site-packages/django/template/base.py", line 977, in render
    return SafeString(''.join([
  File "/home/matt/.local/lib/python3.8/site-packages/django/template/base.py", line 978, in <listcomp>
    node.render_annotated(context) for node in self
  File "/home/matt/.local/lib/python3.8/site-packages/django/template/base.py", line 938, in render_annotated
    return self.render(context)
  File "/home/matt/.local/lib/python3.8/site-packages/django/template/defaulttags.py", line 295, in render
    return nodelist.render(context)
  File "/home/matt/.local/lib/python3.8/site-packages/django/template/base.py", line 977, in render
    return SafeString(''.join([
  File "/home/matt/.local/lib/python3.8/site-packages/django/template/base.py", line 978, in <listcomp>
    node.render_annotated(context) for node in self
  File "/home/matt/.local/lib/python3.8/site-packages/django/template/base.py", line 938, in render_annotated
    return self.render(context)
  File "/home/matt/.local/lib/python3.8/site-packages/django/template/base.py", line 1044, in render
    return render_value_in_context(output, context)
  File "/home/matt/.local/lib/python3.8/site-packages/django/template/base.py", line 1021, in render_value_in_context
    value = str(value)
  File "/home/matt/.local/lib/python3.8/site-packages/django/utils/html.py", line 377, in <lambda>
    klass.__str__ = lambda self: mark_safe(klass_str(self))
  File "/home/matt/.local/lib/python3.8/site-packages/django/forms/boundfield.py", line 33, in __str__
    return self.as_widget()
  File "/home/matt/.local/lib/python3.8/site-packages/django/forms/boundfield.py", line 92, in as_widget
    return widget.render(
  File "/home/matt/.local/lib/python3.8/site-packages/django/forms/widgets.py", line 246, in render
    context = self.get_context(name, value, attrs)
  File "/home/matt/.local/lib/python3.8/site-packages/django/contrib/admin/widgets.py", line 283, in get_context
    'rendered_widget': self.widget.render(name, value, attrs),
  File "/home/matt/.local/lib/python3.8/site-packages/django/forms/widgets.py", line 246, in render
    context = self.get_context(name, value, attrs)
  File "/home/matt/.local/lib/python3.8/site-packages/django/forms/widgets.py", line 681, in get_context
    context = super().get_context(name, value, attrs)
  File "/home/matt/.local/lib/python3.8/site-packages/django/forms/widgets.py", line 642, in get_context
    context['widget']['optgroups'] = self.optgroups(name, context['widget']['value'], attrs)
  File "/home/matt/.local/lib/python3.8/site-packages/django/forms/widgets.py", line 592, in optgroups
    for index, (option_value, option_label) in enumerate(self.choices):
  File "/home/matt/.local/lib/python3.8/site-packages/django/forms/models.py", line 1190, in __iter__
    for obj in queryset:
  File "/home/matt/.local/lib/python3.8/site-packages/django/db/models/query.py", line 357, in _iterator
    yield from self._iterable_class(self, chunked_fetch=use_chunked_fetch, chunk_size=chunk_size)
  File "/home/matt/.local/lib/python3.8/site-packages/django/db/models/query.py", line 51, in __iter__
    results = compiler.execute_sql(chunked_fetch=self.chunked_fetch, chunk_size=self.chunk_size)
  File "/home/matt/.local/lib/python3.8/site-packages/django/db/models/sql/compiler.py", line 1205, in execute_sql
    cursor.close()
psycopg2.errors.InvalidCursorName: cursor "_django_curs_140349053855488_sync_1" does not exist

ERROR 2022-04-26 13:22:44,314 basehttp 22938 140349053855488 "GET /admin/BASE/email/add/ HTTP/1.1" 500 621183
INFO 2022-04-26 13:23:01,686 basehttp 22938 140349053855488 "GET /admin/ HTTP/1.1" 200 4799
INFO 2022-04-26 13:23:04,588 basehttp 22938 140349053855488 "GET /admin/BASE/mailbox/add/ HTTP/1.1" 200 9072
INFO 2022-04-26 13:23:04,623 basehttp 22938 140349053855488 "GET /admin/jsi18n/ HTTP/1.1" 200 3343
ERROR 2022-04-26 13:23:37,121 log 22938 140349053855488 Internal Server Error: /admin/BASE/mailbox/add/
Traceback (most recent call last):
  File "/home/matt/.local/lib/python3.8/site-packages/django/db/backends/utils.py", line 85, in _execute
    return self.cursor.execute(sql, params)
psycopg2.errors.UndefinedColumn: column "is_active" of relation "BASE_mailbox" does not exist
LINE 1: ...t", "login", "password", "email_from", "use_ssl", "is_active...
                                                             ^


The above exception was the direct cause of the following exception:

Traceback (most recent call last):
  File "/home/matt/.local/lib/python3.8/site-packages/django/core/handlers/exception.py", line 47, in inner
    response = get_response(request)
  File "/home/matt/.local/lib/python3.8/site-packages/django/core/handlers/base.py", line 181, in _get_response
    response = wrapped_callback(request, *callback_args, **callback_kwargs)
  File "/home/matt/.local/lib/python3.8/site-packages/django/contrib/admin/options.py", line 622, in wrapper
    return self.admin_site.admin_view(view)(*args, **kwargs)
  File "/home/matt/.local/lib/python3.8/site-packages/django/utils/decorators.py", line 130, in _wrapped_view
    response = view_func(request, *args, **kwargs)
  File "/home/matt/.local/lib/python3.8/site-packages/django/views/decorators/cache.py", line 56, in _wrapped_view_func
    response = view_func(request, *args, **kwargs)
  File "/home/matt/.local/lib/python3.8/site-packages/django/contrib/admin/sites.py", line 236, in inner
    return view(request, *args, **kwargs)
  File "/home/matt/.local/lib/python3.8/site-packages/django/contrib/admin/options.py", line 1670, in add_view
    return self.changeform_view(request, None, form_url, extra_context)
  File "/home/matt/.local/lib/python3.8/site-packages/django/utils/decorators.py", line 43, in _wrapper
    return bound_method(*args, **kwargs)
  File "/home/matt/.local/lib/python3.8/site-packages/django/utils/decorators.py", line 130, in _wrapped_view
    response = view_func(request, *args, **kwargs)
  File "/home/matt/.local/lib/python3.8/site-packages/django/contrib/admin/options.py", line 1549, in changeform_view
    return self._changeform_view(request, object_id, form_url, extra_context)
  File "/home/matt/.local/lib/python3.8/site-packages/django/contrib/admin/options.py", line 1599, in _changeform_view
    self.save_model(request, new_object, form, not add)
  File "/home/matt/.local/lib/python3.8/site-packages/django/contrib/admin/options.py", line 1108, in save_model
    obj.save()
  File "/home/matt/.local/lib/python3.8/site-packages/django/db/models/base.py", line 743, in save
    self.save_base(using=using, force_insert=force_insert,
  File "/home/matt/.local/lib/python3.8/site-packages/django/db/models/base.py", line 780, in save_base
    updated = self._save_table(
  File "/home/matt/.local/lib/python3.8/site-packages/django/db/models/base.py", line 885, in _save_table
    results = self._do_insert(cls._base_manager, using, fields, returning_fields, raw)
  File "/home/matt/.local/lib/python3.8/site-packages/django/db/models/base.py", line 923, in _do_insert
    return manager._insert(
  File "/home/matt/.local/lib/python3.8/site-packages/django/db/models/manager.py", line 85, in manager_method
    return getattr(self.get_queryset(), name)(*args, **kwargs)
  File "/home/matt/.local/lib/python3.8/site-packages/django/db/models/query.py", line 1301, in _insert
    return query.get_compiler(using=using).execute_sql(returning_fields)
  File "/home/matt/.local/lib/python3.8/site-packages/django/db/models/sql/compiler.py", line 1441, in execute_sql
    cursor.execute(sql, params)
  File "/home/matt/.local/lib/python3.8/site-packages/django/db/backends/utils.py", line 99, in execute
    return super().execute(sql, params)
  File "/home/matt/.local/lib/python3.8/site-packages/django/db/backends/utils.py", line 67, in execute
    return self._execute_with_wrappers(sql, params, many=False, executor=self._execute)
  File "/home/matt/.local/lib/python3.8/site-packages/django/db/backends/utils.py", line 76, in _execute_with_wrappers
    return executor(sql, params, many, context)
  File "/home/matt/.local/lib/python3.8/site-packages/django/db/backends/utils.py", line 85, in _execute
    return self.cursor.execute(sql, params)
  File "/home/matt/.local/lib/python3.8/site-packages/django/db/utils.py", line 90, in __exit__
    raise dj_exc_value.with_traceback(traceback) from exc_value
  File "/home/matt/.local/lib/python3.8/site-packages/django/db/backends/utils.py", line 85, in _execute
    return self.cursor.execute(sql, params)
django.db.utils.ProgrammingError: column "is_active" of relation "BASE_mailbox" does not exist
LINE 1: ...t", "login", "password", "email_from", "use_ssl", "is_active...
                                                             ^

ERROR 2022-04-26 13:23:37,122 basehttp 22938 140349053855488 "POST /admin/BASE/mailbox/add/ HTTP/1.1" 500 192360
INFO 2022-04-26 13:29:33,206 autoreload 24055 139670080530240 Watching for file changes with StatReloader
WARNING 2022-04-26 13:29:34,758 log 24055 139670002665216 Not Found: /
WARNING 2022-04-26 13:29:34,758 basehttp 24055 139670002665216 "GET / HTTP/1.1" 404 2967
INFO 2022-04-26 13:29:37,913 basehttp 24055 139670002665216 "GET /admin/ HTTP/1.1" 302 0
INFO 2022-04-26 13:29:37,934 basehttp 24055 139670002665216 "GET /admin/login/?next=/admin/ HTTP/1.1" 200 2215
INFO 2022-04-26 13:29:42,204 basehttp 24055 139670002665216 "POST /admin/login/?next=/admin/ HTTP/1.1" 200 2376
INFO 2022-04-26 13:29:48,900 basehttp 24055 139670002665216 "POST /admin/login/?next=/admin/ HTTP/1.1" 200 2376
INFO 2022-04-26 13:30:09,918 autoreload 24265 139893481273152 Watching for file changes with StatReloader
INFO 2022-04-26 13:30:13,635 basehttp 24265 139893403408128 "POST /admin/login/?next=/admin/ HTTP/1.1" 302 0
INFO 2022-04-26 13:30:13,679 basehttp 24265 139893403408128 "GET /admin/ HTTP/1.1" 200 4799
INFO 2022-04-26 13:30:17,704 basehttp 24265 139893403408128 "GET /admin/BASE/email/add/ HTTP/1.1" 200 9589
INFO 2022-04-26 13:30:17,739 basehttp 24265 139893403408128 "GET /admin/jsi18n/ HTTP/1.1" 200 3343
INFO 2022-04-26 13:30:32,496 basehttp 24265 139893403408128 "GET /admin/BASE/mailbox/ HTTP/1.1" 200 5640
INFO 2022-04-26 13:30:32,520 basehttp 24265 139893403408128 "GET /static/admin/css/changelists.css HTTP/1.1" 200 6932
INFO 2022-04-26 13:30:32,532 basehttp 24265 139893325952768 "GET /admin/jsi18n/ HTTP/1.1" 200 3343
INFO 2022-04-26 13:30:32,735 basehttp 24265 139893403408128 "GET /static/admin/img/tooltag-add.svg HTTP/1.1" 200 331
INFO 2022-04-26 13:30:34,650 basehttp 24265 139893403408128 "GET /admin/BASE/mailbox/add/ HTTP/1.1" 200 9072
INFO 2022-04-26 13:30:34,691 basehttp 24265 139893403408128 "GET /admin/jsi18n/ HTTP/1.1" 200 3343
INFO 2022-04-26 13:30:38,967 basehttp 24265 139893403408128 "GET /admin/BASE/template/ HTTP/1.1" 200 5647
INFO 2022-04-26 13:30:39,003 basehttp 24265 139893403408128 "GET /admin/jsi18n/ HTTP/1.1" 200 3343
INFO 2022-04-26 13:30:41,241 basehttp 24265 139893403408128 "GET /admin/BASE/template/add/ HTTP/1.1" 200 6338
INFO 2022-04-26 13:30:41,278 basehttp 24265 139893403408128 "GET /admin/jsi18n/ HTTP/1.1" 200 3343
INFO 2022-04-26 13:31:21,338 autoreload 24265 139893481273152 /home/matt/PycharmProjects/mailAPI/BASE/models.py changed, reloading.
INFO 2022-04-26 13:31:21,672 autoreload 24397 140576233162560 Watching for file changes with StatReloader
INFO 2022-04-26 13:35:29,555 autoreload 25631 140034424883008 Watching for file changes with StatReloader
WARNING 2022-04-26 13:35:31,180 log 25631 140034347017984 Not Found: /
WARNING 2022-04-26 13:35:31,180 basehttp 25631 140034347017984 "GET / HTTP/1.1" 404 2967
INFO 2022-04-26 13:35:34,643 basehttp 25631 140034347017984 "GET /admin/ HTTP/1.1" 200 4799
INFO 2022-04-26 13:35:37,301 basehttp 25631 140034347017984 "GET /admin/BASE/template/add/ HTTP/1.1" 200 6839
INFO 2022-04-26 13:35:37,334 basehttp 25631 140034347017984 "GET /admin/jsi18n/ HTTP/1.1" 200 3343
INFO 2022-04-26 13:35:43,454 basehttp 25631 140034347017984 "GET /admin/BASE/template/ HTTP/1.1" 200 5647
INFO 2022-04-26 13:35:43,485 basehttp 25631 140034347017984 "GET /admin/jsi18n/ HTTP/1.1" 200 3343
INFO 2022-04-26 13:35:44,812 basehttp 25631 140034347017984 "GET /admin/BASE/mailbox/ HTTP/1.1" 200 5640
INFO 2022-04-26 13:35:44,848 basehttp 25631 140034347017984 "GET /admin/jsi18n/ HTTP/1.1" 200 3343
INFO 2022-04-26 13:35:46,160 basehttp 25631 140034347017984 "GET /admin/BASE/mailbox/ HTTP/1.1" 200 5640
INFO 2022-04-26 13:35:46,196 basehttp 25631 140034347017984 "GET /admin/jsi18n/ HTTP/1.1" 200 3343
INFO 2022-04-26 13:35:46,790 basehttp 25631 140034347017984 "GET /admin/BASE/email/ HTTP/1.1" 200 5626
INFO 2022-04-26 13:35:46,828 basehttp 25631 140034347017984 "GET /admin/jsi18n/ HTTP/1.1" 200 3343
INFO 2022-04-26 13:35:47,917 basehttp 25631 140034347017984 "GET /admin/BASE/email/add/ HTTP/1.1" 200 9589
INFO 2022-04-26 13:35:47,950 basehttp 25631 140034347017984 "GET /admin/jsi18n/ HTTP/1.1" 200 3343
INFO 2022-04-26 13:35:52,250 basehttp 25631 140034347017984 "GET /admin/BASE/mailbox/add/ HTTP/1.1" 200 9072
INFO 2022-04-26 13:35:52,280 basehttp 25631 140034347017984 "GET /admin/jsi18n/ HTTP/1.1" 200 3343
INFO 2022-04-26 13:36:29,961 basehttp 25631 140034347017984 "POST /admin/BASE/mailbox/add/ HTTP/1.1" 302 0
INFO 2022-04-26 13:36:30,015 basehttp 25631 140034347017984 "GET /admin/BASE/mailbox/ HTTP/1.1" 200 7184
INFO 2022-04-26 13:36:30,055 basehttp 25631 140034347017984 "GET /admin/jsi18n/ HTTP/1.1" 200 3343
INFO 2022-04-26 13:36:30,622 basehttp 25631 140034347017984 "GET /static/admin/img/icon-yes.svg HTTP/1.1" 200 436
INFO 2022-04-26 13:37:11,301 basehttp 25631 140034347017984 "GET /admin/BASE/template/add/ HTTP/1.1" 200 6839
INFO 2022-04-26 13:37:11,341 basehttp 25631 140034347017984 "GET /admin/jsi18n/ HTTP/1.1" 200 3343
INFO 2022-04-26 13:37:56,495 basehttp 25631 140034347017984 "POST /admin/BASE/template/add/ HTTP/1.1" 302 0
INFO 2022-04-26 13:37:56,537 basehttp 25631 140034347017984 "GET /admin/BASE/template/ HTTP/1.1" 200 7198
INFO 2022-04-26 13:37:56,567 basehttp 25631 140034347017984 "GET /admin/jsi18n/ HTTP/1.1" 200 3343
INFO 2022-04-26 13:39:02,392 basehttp 25631 140034347017984 "GET /admin/BASE/mailbox/ HTTP/1.1" 200 6904
INFO 2022-04-26 13:39:02,423 basehttp 25631 140034347017984 "GET /admin/jsi18n/ HTTP/1.1" 200 3343
INFO 2022-04-26 13:39:04,126 basehttp 25631 140034347017984 "GET /admin/BASE/template/ HTTP/1.1" 200 6915
INFO 2022-04-26 13:39:04,159 basehttp 25631 140034347017984 "GET /admin/jsi18n/ HTTP/1.1" 200 3343
INFO 2022-04-26 13:39:06,052 basehttp 25631 140034347017984 "GET /admin/BASE/email/ HTTP/1.1" 200 5626
INFO 2022-04-26 13:39:06,087 basehttp 25631 140034347017984 "GET /admin/jsi18n/ HTTP/1.1" 200 3343
INFO 2022-04-26 13:39:07,978 basehttp 25631 140034347017984 "GET /admin/BASE/email/add/ HTTP/1.1" 200 9828
INFO 2022-04-26 13:39:08,014 basehttp 25631 140034347017984 "GET /admin/jsi18n/ HTTP/1.1" 200 3343
INFO 2022-04-26 13:39:42,828 basehttp 25631 140034347017984 "POST /admin/BASE/email/add/ HTTP/1.1" 200 10338
INFO 2022-04-26 13:39:42,863 basehttp 25631 140034347017984 "GET /admin/jsi18n/ HTTP/1.1" 200 3343
INFO 2022-04-26 13:40:09,326 basehttp 25631 140034347017984 "POST /admin/BASE/email/add/ HTTP/1.1" 200 10160
INFO 2022-04-26 13:40:09,369 basehttp 25631 140034347017984 "GET /admin/jsi18n/ HTTP/1.1" 200 3343
INFO 2022-04-26 13:40:25,504 basehttp 25631 140034347017984 "GET /admin/BASE/mailbox/ HTTP/1.1" 200 6904
INFO 2022-04-26 13:40:25,539 basehttp 25631 140034347017984 "GET /admin/jsi18n/ HTTP/1.1" 200 3343
INFO 2022-04-26 13:40:27,206 basehttp 25631 140034347017984 "GET /admin/BASE/email/ HTTP/1.1" 200 5626
INFO 2022-04-26 13:40:27,233 basehttp 25631 140034347017984 "GET /admin/jsi18n/ HTTP/1.1" 200 3343
INFO 2022-04-26 13:40:30,002 basehttp 25631 140034347017984 "GET /admin/BASE/email/add/ HTTP/1.1" 200 9828
INFO 2022-04-26 13:40:30,037 basehttp 25631 140034347017984 "GET /admin/jsi18n/ HTTP/1.1" 200 3343
INFO 2022-04-26 13:43:18,960 autoreload 26968 140320626829120 Watching for file changes with StatReloader
INFO 2022-04-26 13:43:25,132 autoreload 26968 140320626829120 /home/matt/PycharmProjects/mailAPI/BASE/models.py changed, reloading.
INFO 2022-04-26 13:43:25,388 autoreload 26984 139693629327168 Watching for file changes with StatReloader
WARNING 2022-04-26 13:43:27,898 log 26984 139693551462144 Not Found: /
WARNING 2022-04-26 13:43:27,898 basehttp 26984 139693551462144 "GET / HTTP/1.1" 404 2967
INFO 2022-04-26 13:43:31,880 views 26984 139693551462144 List of mailboxes load successfully
INFO 2022-04-26 13:43:31,902 basehttp 26984 139693551462144 "GET /api/mailbox/ HTTP/1.1" 200 7357
INFO 2022-04-26 13:43:31,923 basehttp 26984 139693551462144 "GET /static/rest_framework/css/bootstrap.min.css HTTP/1.1" 200 121457
INFO 2022-04-26 13:43:31,932 basehttp 26984 139693551462144 "GET /static/rest_framework/css/default.css HTTP/1.1" 304 0
INFO 2022-04-26 13:43:31,933 basehttp 26984 139693449266944 "GET /static/rest_framework/css/bootstrap-tweaks.css HTTP/1.1" 304 0
INFO 2022-04-26 13:43:31,934 basehttp 26984 139693440874240 "GET /static/rest_framework/css/prettify.css HTTP/1.1" 304 0
INFO 2022-04-26 13:43:31,935 basehttp 26984 139693457659648 "GET /static/rest_framework/js/prettify-min.js HTTP/1.1" 200 13632
INFO 2022-04-26 13:43:31,935 basehttp 26984 139693466052352 "GET /static/rest_framework/js/bootstrap.min.js HTTP/1.1" 200 39680
INFO 2022-04-26 13:43:31,936 basehttp 26984 139693475755776 "GET /static/rest_framework/js/jquery-3.5.1.min.js HTTP/1.1" 200 89476
INFO 2022-04-26 13:43:31,938 basehttp 26984 139693440874240 "GET /static/rest_framework/js/default.js HTTP/1.1" 304 0
INFO 2022-04-26 13:43:31,939 basehttp 26984 139693449266944 "GET /static/rest_framework/js/csrf.js HTTP/1.1" 304 0
INFO 2022-04-26 13:43:31,939 basehttp 26984 139693551462144 "GET /static/rest_framework/js/ajax-form.js HTTP/1.1" 304 0
INFO 2022-04-26 13:43:32,044 basehttp 26984 139693551462144 "GET /static/rest_framework/img/grid.png HTTP/1.1" 304 0
INFO 2022-04-26 13:43:40,898 basehttp 26984 139693551462144 "OPTIONS /api/mailbox/ HTTP/1.1" 200 7269
INFO 2022-04-26 13:43:43,123 basehttp 26984 139693551462144 "OPTIONS /api/mailbox/ HTTP/1.1" 200 7269
INFO 2022-04-26 13:43:43,957 basehttp 26984 139693551462144 "OPTIONS /api/mailbox/ HTTP/1.1" 200 7269
INFO 2022-04-26 13:43:52,567 basehttp 26984 139693551462144 "OPTIONS /api/mailbox/ HTTP/1.1" 200 7269
INFO 2022-04-26 13:44:01,003 views 26984 139693551462144 List of mailboxes load successfully
INFO 2022-04-26 13:44:01,017 basehttp 26984 139693551462144 "GET /api/mailbox/ HTTP/1.1" 200 7357
WARNING 2022-04-26 13:44:42,121 log 26984 139693551462144 Bad Request: /api/mailbox/
WARNING 2022-04-26 13:44:42,121 basehttp 26984 139693551462144 "POST /api/mailbox/ HTTP/1.1" 400 7012
INFO 2022-04-26 13:45:01,474 views 26984 139693551462144 List of mailboxes load successfully
INFO 2022-04-26 13:45:01,488 basehttp 26984 139693551462144 "GET /api/mailbox/ HTTP/1.1" 200 7357
WARNING 2022-04-26 13:45:16,496 log 26984 139693551462144 Bad Request: /api/mailbox/
WARNING 2022-04-26 13:45:16,496 basehttp 26984 139693551462144 "POST /api/mailbox/ HTTP/1.1" 400 7013
WARNING 2022-04-26 13:45:42,920 log 26984 139693551462144 Not Found: /
WARNING 2022-04-26 13:45:42,921 basehttp 26984 139693551462144 "GET / HTTP/1.1" 404 2967
INFO 2022-04-26 13:45:48,023 views 26984 139693551462144 List of mailboxes load successfully
INFO 2022-04-26 13:45:48,046 basehttp 26984 139693551462144 "GET /api/mailbox/ HTTP/1.1" 200 7357
WARNING 2022-04-26 13:46:11,250 log 26984 139693551462144 Bad Request: /api/mailbox/
WARNING 2022-04-26 13:46:11,251 basehttp 26984 139693551462144 "POST /api/mailbox/ HTTP/1.1" 400 7026
INFO 2022-04-26 13:46:32,596 views 26984 139693551462144 CREATED
INFO 2022-04-26 13:46:32,615 basehttp 26984 139693551462144 "POST /api/mailbox/ HTTP/1.1" 201 7318
INFO 2022-04-26 13:46:40,733 views 26984 139693551462144 List of mailboxes load successfully
INFO 2022-04-26 13:46:40,751 basehttp 26984 139693551462144 "GET /api/mailbox/ HTTP/1.1" 200 7815
INFO 2022-04-28 18:12:49,368 autoreload 9277 140650117998400 Watching for file changes with StatReloader
WARNING 2022-04-28 18:12:51,519 log 9277 140649972889344 Not Found: /
WARNING 2022-04-28 18:12:51,519 basehttp 9277 140649972889344 "GET / HTTP/1.1" 404 2237
WARNING 2022-04-28 18:12:52,168 log 9277 140649972889344 Not Found: /favicon.ico
WARNING 2022-04-28 18:12:52,168 basehttp 9277 140649972889344 "GET /favicon.ico HTTP/1.1" 404 2288
WARNING 2022-04-28 18:12:54,188 log 9277 140649972889344 Method Not Allowed: /api/mailbox/
WARNING 2022-04-28 18:12:54,189 basehttp 9277 140649972889344 "GET /api/mailbox/ HTTP/1.1" 405 3987
INFO 2022-04-28 18:12:54,211 basehttp 9277 140649972889344 "GET /static/rest_framework/css/bootstrap.min.css HTTP/1.1" 200 121457
INFO 2022-04-28 18:12:54,215 basehttp 9277 140649964496640 "GET /static/rest_framework/css/bootstrap-tweaks.css HTTP/1.1" 200 3385
INFO 2022-04-28 18:12:54,219 basehttp 9277 140649972889344 "GET /static/rest_framework/js/csrf.js HTTP/1.1" 304 0
INFO 2022-04-28 18:12:54,219 basehttp 9277 140649938269952 "GET /static/rest_framework/css/prettify.css HTTP/1.1" 304 0
INFO 2022-04-28 18:12:54,220 basehttp 9277 140649929877248 "GET /static/rest_framework/css/default.css HTTP/1.1" 304 0
INFO 2022-04-28 18:12:54,221 basehttp 9277 140649946662656 "GET /static/rest_framework/js/ajax-form.js HTTP/1.1" 200 3597
INFO 2022-04-28 18:12:54,222 basehttp 9277 140649955055360 "GET /static/rest_framework/js/jquery-3.5.1.min.js HTTP/1.1" 200 89476
INFO 2022-04-28 18:12:54,223 basehttp 9277 140649964496640 "GET /static/rest_framework/js/bootstrap.min.js HTTP/1.1" 200 39680
INFO 2022-04-28 18:12:54,226 basehttp 9277 140649955055360 "GET /static/rest_framework/js/default.js HTTP/1.1" 304 0
INFO 2022-04-28 18:12:54,227 basehttp 9277 140649929877248 "GET /static/rest_framework/js/prettify-min.js HTTP/1.1" 200 13632
INFO 2022-04-28 18:12:55,092 basehttp 9277 140649964496640 "GET /static/rest_framework/img/grid.png HTTP/1.1" 304 0
INFO 2022-04-28 18:13:29,300 autoreload 9277 140650117998400 /home/matt/PycharmProjects/mailAPI/BASE/views.py changed, reloading.
INFO 2022-04-28 18:13:29,591 autoreload 9528 140505033799488 Watching for file changes with StatReloader
INFO 2022-04-28 18:15:39,881 autoreload 9528 140505033799488 /home/matt/PycharmProjects/mailAPI/BASE/views.py changed, reloading.
INFO 2022-04-28 18:15:40,219 autoreload 9701 140226578085696 Watching for file changes with StatReloader
WARNING 2022-04-28 18:15:40,448 log 9701 140226500744960 Method Not Allowed: /api/mailbox/
WARNING 2022-04-28 18:15:40,449 basehttp 9701 140226500744960 "GET /api/mailbox/ HTTP/1.1" 405 3733
INFO 2022-04-28 18:15:54,698 autoreload 9701 140226578085696 /home/matt/PycharmProjects/mailAPI/BASE/views.py changed, reloading.
INFO 2022-04-28 18:15:55,013 autoreload 9730 140343694149440 Watching for file changes with StatReloader
ERROR 2022-04-28 18:15:56,109 log 9730 140343616808704 Internal Server Error: /api/mailbox/
Traceback (most recent call last):
  File "/home/matt/.local/lib/python3.8/site-packages/django/core/handlers/exception.py", line 47, in inner
    response = get_response(request)
  File "/home/matt/.local/lib/python3.8/site-packages/django/core/handlers/base.py", line 181, in _get_response
    response = wrapped_callback(request, *callback_args, **callback_kwargs)
  File "/home/matt/.local/lib/python3.8/site-packages/django/views/decorators/csrf.py", line 54, in wrapped_view
    return view_func(*args, **kwargs)
  File "/home/matt/.local/lib/python3.8/site-packages/django/views/generic/base.py", line 69, in view
    return self.dispatch(request, *args, **kwargs)
  File "/usr/local/lib/python3.8/dist-packages/rest_framework/views.py", line 509, in dispatch
    response = self.handle_exception(exc)
  File "/usr/local/lib/python3.8/dist-packages/rest_framework/views.py", line 469, in handle_exception
    self.raise_uncaught_exception(exc)
  File "/usr/local/lib/python3.8/dist-packages/rest_framework/views.py", line 480, in raise_uncaught_exception
    raise exc
  File "/usr/local/lib/python3.8/dist-packages/rest_framework/views.py", line 506, in dispatch
    response = handler(request, *args, **kwargs)
TypeError: get() takes 1 positional argument but 2 were given
ERROR 2022-04-28 18:15:56,109 basehttp 9730 140343616808704 "GET /api/mailbox/ HTTP/1.1" 500 91461
INFO 2022-04-28 18:16:43,054 autoreload 9730 140343694149440 /home/matt/PycharmProjects/mailAPI/BASE/views.py changed, reloading.
INFO 2022-04-28 18:16:43,341 autoreload 9790 139962527319872 Watching for file changes with StatReloader
ERROR 2022-04-28 18:16:44,421 log 9790 139962380973824 Internal Server Error: /api/mailbox/
Traceback (most recent call last):
  File "/home/matt/.local/lib/python3.8/site-packages/django/core/handlers/exception.py", line 47, in inner
    response = get_response(request)
  File "/home/matt/.local/lib/python3.8/site-packages/django/core/handlers/base.py", line 181, in _get_response
    response = wrapped_callback(request, *callback_args, **callback_kwargs)
  File "/home/matt/.local/lib/python3.8/site-packages/django/views/decorators/csrf.py", line 54, in wrapped_view
    return view_func(*args, **kwargs)
  File "/home/matt/.local/lib/python3.8/site-packages/django/views/generic/base.py", line 69, in view
    return self.dispatch(request, *args, **kwargs)
  File "/usr/local/lib/python3.8/dist-packages/rest_framework/views.py", line 511, in dispatch
    self.response = self.finalize_response(request, response, *args, **kwargs)
  File "/usr/local/lib/python3.8/dist-packages/rest_framework/views.py", line 423, in finalize_response
    assert isinstance(response, HttpResponseBase), (
AssertionError: Expected a `Response`, `HttpResponse` or `HttpStreamingResponse` to be returned from the view, but received a `<class 'django.db.models.query.QuerySet'>`
ERROR 2022-04-28 18:16:44,421 basehttp 9790 139962380973824 "GET /api/mailbox/ HTTP/1.1" 500 83374
INFO 2022-04-28 18:17:06,941 autoreload 9790 139962527319872 /home/matt/PycharmProjects/mailAPI/BASE/views.py changed, reloading.
INFO 2022-04-28 18:17:07,237 autoreload 9815 140164281755456 Watching for file changes with StatReloader
ERROR 2022-04-28 18:17:07,699 log 9815 140164204414720 Internal Server Error: /api/mailbox/
Traceback (most recent call last):
  File "/home/matt/.local/lib/python3.8/site-packages/django/core/handlers/exception.py", line 47, in inner
    response = get_response(request)
  File "/home/matt/.local/lib/python3.8/site-packages/django/core/handlers/base.py", line 204, in _get_response
    response = response.render()
  File "/home/matt/.local/lib/python3.8/site-packages/django/template/response.py", line 105, in render
    self.content = self.rendered_content
  File "/usr/local/lib/python3.8/dist-packages/rest_framework/response.py", line 70, in rendered_content
    ret = renderer.render(self.data, accepted_media_type, context)
  File "/usr/local/lib/python3.8/dist-packages/rest_framework/renderers.py", line 724, in render
    context = self.get_context(data, accepted_media_type, renderer_context)
  File "/usr/local/lib/python3.8/dist-packages/rest_framework/renderers.py", line 680, in get_context
    'content': self.get_content(renderer, data, accepted_media_type, renderer_context),
  File "/usr/local/lib/python3.8/dist-packages/rest_framework/renderers.py", line 413, in get_content
    content = renderer.render(data, accepted_media_type, renderer_context)
  File "/usr/local/lib/python3.8/dist-packages/rest_framework/renderers.py", line 100, in render
    ret = json.dumps(
  File "/usr/local/lib/python3.8/dist-packages/rest_framework/utils/json.py", line 25, in dumps
    return json.dumps(*args, **kwargs)
  File "/usr/lib/python3.8/json/__init__.py", line 234, in dumps
    return cls(
  File "/usr/lib/python3.8/json/encoder.py", line 201, in encode
    chunks = list(chunks)
  File "/usr/lib/python3.8/json/encoder.py", line 439, in _iterencode
    yield from _iterencode(o, _current_indent_level)
  File "/usr/lib/python3.8/json/encoder.py", line 429, in _iterencode
    yield from _iterencode_list(o, _current_indent_level)
  File "/usr/lib/python3.8/json/encoder.py", line 325, in _iterencode_list
    yield from chunks
  File "/usr/lib/python3.8/json/encoder.py", line 438, in _iterencode
    o = _default(o)
  File "/usr/local/lib/python3.8/dist-packages/rest_framework/utils/encoders.py", line 67, in default
    return super().default(obj)
  File "/usr/lib/python3.8/json/encoder.py", line 179, in default
    raise TypeError(f'Object of type {o.__class__.__name__} '
TypeError: Object of type Mailbox is not JSON serializable
ERROR 2022-04-28 18:17:07,700 basehttp 9815 140164204414720 "GET /api/mailbox/ HTTP/1.1" 500 149856
INFO 2022-04-28 18:17:28,795 autoreload 9815 140164281755456 /home/matt/PycharmProjects/mailAPI/BASE/views.py changed, reloading.
INFO 2022-04-28 18:17:29,117 autoreload 9847 140139370714944 Watching for file changes with StatReloader
ERROR 2022-04-28 18:17:30,753 log 9847 140139292849920 Internal Server Error: /api/mailbox/
Traceback (most recent call last):
  File "/home/matt/.local/lib/python3.8/site-packages/django/core/handlers/exception.py", line 47, in inner
    response = get_response(request)
  File "/home/matt/.local/lib/python3.8/site-packages/django/core/handlers/base.py", line 181, in _get_response
    response = wrapped_callback(request, *callback_args, **callback_kwargs)
  File "/home/matt/.local/lib/python3.8/site-packages/django/views/decorators/csrf.py", line 54, in wrapped_view
    return view_func(*args, **kwargs)
  File "/home/matt/.local/lib/python3.8/site-packages/django/views/generic/base.py", line 69, in view
    return self.dispatch(request, *args, **kwargs)
  File "/usr/local/lib/python3.8/dist-packages/rest_framework/views.py", line 509, in dispatch
    response = self.handle_exception(exc)
  File "/usr/local/lib/python3.8/dist-packages/rest_framework/views.py", line 469, in handle_exception
    self.raise_uncaught_exception(exc)
  File "/usr/local/lib/python3.8/dist-packages/rest_framework/views.py", line 480, in raise_uncaught_exception
    raise exc
  File "/usr/local/lib/python3.8/dist-packages/rest_framework/views.py", line 506, in dispatch
    response = handler(request, *args, **kwargs)
  File "/home/matt/PycharmProjects/mailAPI/BASE/views.py", line 17, in get
    return Response(serializer)
  File "/usr/local/lib/python3.8/dist-packages/rest_framework/response.py", line 38, in __init__
    raise AssertionError(msg)
AssertionError: You passed a Serializer instance as data, but probably meant to pass serialized `.data` or `.error`. representation.
ERROR 2022-04-28 18:17:30,754 basehttp 9847 140139292849920 "GET /api/mailbox/ HTTP/1.1" 500 102595
ERROR 2022-04-28 18:17:39,342 log 9847 140139292849920 Internal Server Error: /api/mailbox/
Traceback (most recent call last):
  File "/home/matt/.local/lib/python3.8/site-packages/django/core/handlers/exception.py", line 47, in inner
    response = get_response(request)
  File "/home/matt/.local/lib/python3.8/site-packages/django/core/handlers/base.py", line 181, in _get_response
    response = wrapped_callback(request, *callback_args, **callback_kwargs)
  File "/home/matt/.local/lib/python3.8/site-packages/django/views/decorators/csrf.py", line 54, in wrapped_view
    return view_func(*args, **kwargs)
  File "/home/matt/.local/lib/python3.8/site-packages/django/views/generic/base.py", line 69, in view
    return self.dispatch(request, *args, **kwargs)
  File "/usr/local/lib/python3.8/dist-packages/rest_framework/views.py", line 509, in dispatch
    response = self.handle_exception(exc)
  File "/usr/local/lib/python3.8/dist-packages/rest_framework/views.py", line 469, in handle_exception
    self.raise_uncaught_exception(exc)
  File "/usr/local/lib/python3.8/dist-packages/rest_framework/views.py", line 480, in raise_uncaught_exception
    raise exc
  File "/usr/local/lib/python3.8/dist-packages/rest_framework/views.py", line 506, in dispatch
    response = handler(request, *args, **kwargs)
  File "/home/matt/PycharmProjects/mailAPI/BASE/views.py", line 17, in get
    return Response(serializer.data)
  File "/usr/local/lib/python3.8/dist-packages/rest_framework/response.py", line 38, in __init__
    raise AssertionError(msg)
AssertionError: You passed a Serializer instance as data, but probably meant to pass serialized `.data` or `.error`. representation.
ERROR 2022-04-28 18:17:39,343 basehttp 9847 140139292849920 "GET /api/mailbox/ HTTP/1.1" 500 102605
INFO 2022-04-28 18:17:39,539 autoreload 9847 140139370714944 /home/matt/PycharmProjects/mailAPI/BASE/views.py changed, reloading.
INFO 2022-04-28 18:17:39,832 autoreload 9860 140199775987520 Watching for file changes with StatReloader
ERROR 2022-04-28 18:17:40,896 log 9860 140199698646784 Internal Server Error: /api/mailbox/
Traceback (most recent call last):
  File "/usr/local/lib/python3.8/dist-packages/rest_framework/fields.py", line 457, in get_attribute
    return get_attribute(instance, self.source_attrs)
  File "/usr/local/lib/python3.8/dist-packages/rest_framework/fields.py", line 97, in get_attribute
    instance = getattr(instance, attr)
AttributeError: 'QuerySet' object has no attribute 'host'

During handling of the above exception, another exception occurred:

Traceback (most recent call last):
  File "/home/matt/.local/lib/python3.8/site-packages/django/core/handlers/exception.py", line 47, in inner
    response = get_response(request)
  File "/home/matt/.local/lib/python3.8/site-packages/django/core/handlers/base.py", line 181, in _get_response
    response = wrapped_callback(request, *callback_args, **callback_kwargs)
  File "/home/matt/.local/lib/python3.8/site-packages/django/views/decorators/csrf.py", line 54, in wrapped_view
    return view_func(*args, **kwargs)
  File "/home/matt/.local/lib/python3.8/site-packages/django/views/generic/base.py", line 69, in view
    return self.dispatch(request, *args, **kwargs)
  File "/usr/local/lib/python3.8/dist-packages/rest_framework/views.py", line 509, in dispatch
    response = self.handle_exception(exc)
  File "/usr/local/lib/python3.8/dist-packages/rest_framework/views.py", line 469, in handle_exception
    self.raise_uncaught_exception(exc)
  File "/usr/local/lib/python3.8/dist-packages/rest_framework/views.py", line 480, in raise_uncaught_exception
    raise exc
  File "/usr/local/lib/python3.8/dist-packages/rest_framework/views.py", line 506, in dispatch
    response = handler(request, *args, **kwargs)
  File "/home/matt/PycharmProjects/mailAPI/BASE/views.py", line 17, in get
    return Response(serializer.data)
  File "/usr/local/lib/python3.8/dist-packages/rest_framework/serializers.py", line 555, in data
    ret = super().data
  File "/usr/local/lib/python3.8/dist-packages/rest_framework/serializers.py", line 253, in data
    self._data = self.to_representation(self.instance)
  File "/usr/local/lib/python3.8/dist-packages/rest_framework/serializers.py", line 509, in to_representation
    attribute = field.get_attribute(instance)
  File "/usr/local/lib/python3.8/dist-packages/rest_framework/fields.py", line 490, in get_attribute
    raise type(exc)(msg)
AttributeError: Got AttributeError when attempting to get a value for field `host` on serializer `MailboxSerializer`.
The serializer field might be named incorrectly and not match any attribute or key on the `QuerySet` instance.
Original exception text was: 'QuerySet' object has no attribute 'host'.
ERROR 2022-04-28 18:17:40,897 basehttp 9860 140199698646784 "GET /api/mailbox/ HTTP/1.1" 500 125282
INFO 2022-04-28 18:18:40,011 autoreload 9860 140199775987520 /home/matt/PycharmProjects/mailAPI/BASE/views.py changed, reloading.
INFO 2022-04-28 18:18:40,326 autoreload 9947 139842431944512 Watching for file changes with StatReloader
INFO 2022-04-28 18:18:41,285 basehttp 9947 139842354603776 "GET /api/mailbox/ HTTP/1.1" 200 5855
INFO 2022-04-28 18:18:41,844 basehttp 9947 139842354603776 "GET /api/mailbox/ HTTP/1.1" 200 5855
INFO 2022-04-28 18:18:47,648 autoreload 9947 139842431944512 /home/matt/PycharmProjects/mailAPI/BASE/views.py changed, reloading.
INFO 2022-04-28 18:18:47,965 autoreload 9997 140500030355264 Watching for file changes with StatReloader
ERROR 2022-04-28 18:18:48,850 log 9997 140499953014528 Internal Server Error: /api/mailbox/
Traceback (most recent call last):
  File "/home/matt/.local/lib/python3.8/site-packages/django/core/handlers/exception.py", line 47, in inner
    response = get_response(request)
  File "/home/matt/.local/lib/python3.8/site-packages/django/core/handlers/base.py", line 181, in _get_response
    response = wrapped_callback(request, *callback_args, **callback_kwargs)
  File "/home/matt/.local/lib/python3.8/site-packages/django/views/decorators/csrf.py", line 54, in wrapped_view
    return view_func(*args, **kwargs)
  File "/home/matt/.local/lib/python3.8/site-packages/django/views/generic/base.py", line 69, in view
    return self.dispatch(request, *args, **kwargs)
  File "/usr/local/lib/python3.8/dist-packages/rest_framework/views.py", line 509, in dispatch
    response = self.handle_exception(exc)
  File "/usr/local/lib/python3.8/dist-packages/rest_framework/views.py", line 469, in handle_exception
    self.raise_uncaught_exception(exc)
  File "/usr/local/lib/python3.8/dist-packages/rest_framework/views.py", line 480, in raise_uncaught_exception
    raise exc
  File "/usr/local/lib/python3.8/dist-packages/rest_framework/views.py", line 506, in dispatch
    response = handler(request, *args, **kwargs)
TypeError: get() takes 1 positional argument but 2 were given
ERROR 2022-04-28 18:18:48,850 basehttp 9997 140499953014528 "GET /api/mailbox/ HTTP/1.1" 500 91461
ERROR 2022-04-28 18:18:49,407 log 9997 140499953014528 Internal Server Error: /api/mailbox/
Traceback (most recent call last):
  File "/home/matt/.local/lib/python3.8/site-packages/django/core/handlers/exception.py", line 47, in inner
    response = get_response(request)
  File "/home/matt/.local/lib/python3.8/site-packages/django/core/handlers/base.py", line 181, in _get_response
    response = wrapped_callback(request, *callback_args, **callback_kwargs)
  File "/home/matt/.local/lib/python3.8/site-packages/django/views/decorators/csrf.py", line 54, in wrapped_view
    return view_func(*args, **kwargs)
  File "/home/matt/.local/lib/python3.8/site-packages/django/views/generic/base.py", line 69, in view
    return self.dispatch(request, *args, **kwargs)
  File "/usr/local/lib/python3.8/dist-packages/rest_framework/views.py", line 509, in dispatch
    response = self.handle_exception(exc)
  File "/usr/local/lib/python3.8/dist-packages/rest_framework/views.py", line 469, in handle_exception
    self.raise_uncaught_exception(exc)
  File "/usr/local/lib/python3.8/dist-packages/rest_framework/views.py", line 480, in raise_uncaught_exception
    raise exc
  File "/usr/local/lib/python3.8/dist-packages/rest_framework/views.py", line 506, in dispatch
    response = handler(request, *args, **kwargs)
TypeError: get() takes 1 positional argument but 2 were given
ERROR 2022-04-28 18:18:49,408 basehttp 9997 140499953014528 "GET /api/mailbox/ HTTP/1.1" 500 91461
INFO 2022-04-28 18:19:12,594 autoreload 9997 140500030355264 /home/matt/PycharmProjects/mailAPI/BASE/views.py changed, reloading.
INFO 2022-04-28 18:19:12,895 autoreload 10065 140247432292160 Watching for file changes with StatReloader
INFO 2022-04-28 18:19:24,270 autoreload 10065 140247432292160 /home/matt/PycharmProjects/mailAPI/BASE/views.py changed, reloading.
INFO 2022-04-28 18:19:24,594 autoreload 10084 140618483746624 Watching for file changes with StatReloader
INFO 2022-04-28 18:19:25,418 basehttp 10084 140618406405888 "GET /api/mailbox/ HTTP/1.1" 200 5855
INFO 2022-04-28 18:19:25,967 basehttp 10084 140618406405888 "GET /api/mailbox/ HTTP/1.1" 200 5855
INFO 2022-04-28 18:21:39,888 autoreload 10084 140618483746624 /home/matt/PycharmProjects/mailAPI/BASE/views.py changed, reloading.
INFO 2022-04-28 18:21:40,214 autoreload 10243 139622522746688 Watching for file changes with StatReloader
INFO 2022-04-28 18:21:41,195 views 10243 139622445405952 List of mailboxes load successfully
INFO 2022-04-28 18:21:41,224 basehttp 10243 139622445405952 "GET /api/mailbox/ HTTP/1.1" 200 7503
INFO 2022-04-28 18:22:26,212 autoreload 10243 139622522746688 /home/matt/PycharmProjects/mailAPI/BASE/views.py changed, reloading.
INFO 2022-04-28 18:22:26,538 autoreload 10296 140070926878528 Watching for file changes with StatReloader
INFO 2022-04-28 18:24:05,378 autoreload 10296 140070926878528 /home/matt/PycharmProjects/mailAPI/BASE/views.py changed, reloading.
INFO 2022-04-28 18:24:05,671 autoreload 10489 139709499668288 Watching for file changes with StatReloader
INFO 2022-04-28 18:24:06,561 views 10489 139709422327552 List of mailboxes load successfully
INFO 2022-04-28 18:24:06,585 basehttp 10489 139709422327552 "GET /api/mailbox/ HTTP/1.1" 200 7765
INFO 2022-04-28 18:25:35,347 autoreload 10489 139709499668288 /home/matt/PycharmProjects/mailAPI/BASE/views.py changed, reloading.
INFO 2022-04-28 18:25:35,637 autoreload 10663 140186370766656 Watching for file changes with StatReloader
INFO 2022-04-28 18:25:35,981 views 10663 140186293425920 List of mailboxes load successfully
INFO 2022-04-28 18:25:36,004 basehttp 10663 140186293425920 "GET /api/mailbox/ HTTP/1.1" 200 7765
INFO 2022-04-28 18:26:01,270 autoreload 10663 140186370766656 /home/matt/PycharmProjects/mailAPI/BASE/views.py changed, reloading.
INFO 2022-04-28 18:26:01,564 autoreload 10718 140669933782848 Watching for file changes with StatReloader
INFO 2022-04-28 18:26:32,301 autoreload 10718 140669933782848 /home/matt/PycharmProjects/mailAPI/BASE/urls.py changed, reloading.
INFO 2022-04-28 18:26:32,563 autoreload 10744 140130440947520 Watching for file changes with StatReloader
INFO 2022-04-28 18:27:45,938 autoreload 10744 140130440947520 /home/matt/PycharmProjects/mailAPI/BASE/views.py changed, reloading.
INFO 2022-04-28 18:27:46,285 autoreload 10881 140319910369088 Watching for file changes with StatReloader
INFO 2022-04-28 18:29:06,687 autoreload 10881 140319910369088 /home/matt/PycharmProjects/mailAPI/BASE/views.py changed, reloading.
INFO 2022-04-28 18:29:06,988 autoreload 11045 140715663894336 Watching for file changes with StatReloader
INFO 2022-04-28 18:29:08,664 views 11045 140715586029312 List of mailboxes load successfully
INFO 2022-04-28 18:29:08,692 basehttp 11045 140715586029312 "GET /api/mailbox/ HTTP/1.1" 200 7765
WARNING 2022-04-28 18:29:12,658 log 11045 140715586029312 Not Found: /api/mailbox/1
WARNING 2022-04-28 18:29:12,659 basehttp 11045 140715586029312 "GET /api/mailbox/1 HTTP/1.1" 404 2484
WARNING 2022-04-28 18:29:19,186 log 11045 140715586029312 Not Found: /api/mailbox/2
WARNING 2022-04-28 18:29:19,187 basehttp 11045 140715586029312 "GET /api/mailbox/2 HTTP/1.1" 404 2484
INFO 2022-04-28 18:31:54,334 views 11045 140715586029312 List of mailboxes load successfully
INFO 2022-04-28 18:31:54,352 basehttp 11045 140715586029312 "GET /api/mailbox/ HTTP/1.1" 200 7765
INFO 2022-04-28 18:31:54,938 autoreload 11045 140715663894336 /home/matt/PycharmProjects/mailAPI/BASE/serializers.py changed, reloading.
INFO 2022-04-28 18:31:55,262 autoreload 11424 140214700222272 Watching for file changes with StatReloader
INFO 2022-04-28 18:32:22,090 views 11424 140214622357248 List of mailboxes load successfully
INFO 2022-04-28 18:32:22,114 basehttp 11424 140214622357248 "GET /api/mailbox/ HTTP/1.1" 200 7913
ERROR 2022-04-28 18:32:31,380 log 11424 140214622357248 Internal Server Error: /api/mailbox/aa6092de-2ad2-4946-a201-c2ec5fbcb686
Traceback (most recent call last):
  File "/home/matt/.local/lib/python3.8/site-packages/django/core/handlers/exception.py", line 47, in inner
    response = get_response(request)
  File "/home/matt/.local/lib/python3.8/site-packages/django/core/handlers/base.py", line 181, in _get_response
    response = wrapped_callback(request, *callback_args, **callback_kwargs)
  File "/home/matt/.local/lib/python3.8/site-packages/django/views/decorators/csrf.py", line 54, in wrapped_view
    return view_func(*args, **kwargs)
  File "/home/matt/.local/lib/python3.8/site-packages/django/views/generic/base.py", line 69, in view
    return self.dispatch(request, *args, **kwargs)
  File "/usr/local/lib/python3.8/dist-packages/rest_framework/views.py", line 509, in dispatch
    response = self.handle_exception(exc)
  File "/usr/local/lib/python3.8/dist-packages/rest_framework/views.py", line 469, in handle_exception
    self.raise_uncaught_exception(exc)
  File "/usr/local/lib/python3.8/dist-packages/rest_framework/views.py", line 480, in raise_uncaught_exception
    raise exc
  File "/usr/local/lib/python3.8/dist-packages/rest_framework/views.py", line 506, in dispatch
    response = handler(request, *args, **kwargs)
TypeError: get() got an unexpected keyword argument 'id'
ERROR 2022-04-28 18:32:31,380 basehttp 11424 140214622357248 "GET /api/mailbox/aa6092de-2ad2-4946-a201-c2ec5fbcb686 HTTP/1.1" 500 92292
INFO 2022-04-28 18:35:42,174 autoreload 11424 140214700222272 /home/matt/PycharmProjects/mailAPI/BASE/urls.py changed, reloading.
INFO 2022-04-28 18:35:42,440 autoreload 11899 140712973518656 Watching for file changes with StatReloader
WARNING 2022-04-28 18:35:46,758 log 11899 140712895653632 Not Found: /api/mailbox/aa6092de-2ad2-4946-a201-c2ec5fbcb686
WARNING 2022-04-28 18:35:46,758 basehttp 11899 140712895653632 "GET /api/mailbox/aa6092de-2ad2-4946-a201-c2ec5fbcb686 HTTP/1.1" 404 2588
WARNING 2022-04-28 18:35:57,874 log 11899 140712895653632 Not Found: /api/mailbox/aa6092de-2ad2-4946-a201-c2ec5fbcb686
WARNING 2022-04-28 18:35:57,874 basehttp 11899 140712895653632 "GET /api/mailbox/aa6092de-2ad2-4946-a201-c2ec5fbcb686 HTTP/1.1" 404 2588
INFO 2022-04-28 18:35:58,004 autoreload 11899 140712973518656 /home/matt/PycharmProjects/mailAPI/BASE/urls.py changed, reloading.
INFO 2022-04-28 18:35:58,317 autoreload 11923 139940230440768 Watching for file changes with StatReloader
ERROR 2022-04-28 18:36:02,720 log 11923 139940152575744 Internal Server Error: /api/mailbox/aa6092de-2ad2-4946-a201-c2ec5fbcb686
Traceback (most recent call last):
  File "/home/matt/.local/lib/python3.8/site-packages/django/core/handlers/exception.py", line 47, in inner
    response = get_response(request)
  File "/home/matt/.local/lib/python3.8/site-packages/django/core/handlers/base.py", line 181, in _get_response
    response = wrapped_callback(request, *callback_args, **callback_kwargs)
  File "/home/matt/.local/lib/python3.8/site-packages/django/views/decorators/csrf.py", line 54, in wrapped_view
    return view_func(*args, **kwargs)
  File "/home/matt/.local/lib/python3.8/site-packages/django/views/generic/base.py", line 69, in view
    return self.dispatch(request, *args, **kwargs)
  File "/usr/local/lib/python3.8/dist-packages/rest_framework/views.py", line 509, in dispatch
    response = self.handle_exception(exc)
  File "/usr/local/lib/python3.8/dist-packages/rest_framework/views.py", line 469, in handle_exception
    self.raise_uncaught_exception(exc)
  File "/usr/local/lib/python3.8/dist-packages/rest_framework/views.py", line 480, in raise_uncaught_exception
    raise exc
  File "/usr/local/lib/python3.8/dist-packages/rest_framework/views.py", line 506, in dispatch
    response = handler(request, *args, **kwargs)
TypeError: get() got an unexpected keyword argument 'id'
ERROR 2022-04-28 18:36:02,721 basehttp 11923 139940152575744 "GET /api/mailbox/aa6092de-2ad2-4946-a201-c2ec5fbcb686 HTTP/1.1" 500 92393
INFO 2022-04-28 18:39:33,532 views 11923 139940152575744 List of mailboxes load successfully
INFO 2022-04-28 18:39:33,552 basehttp 11923 139940152575744 "GET /api/mailbox/ HTTP/1.1" 200 7913
INFO 2022-04-28 18:40:02,115 views 11923 139940152575744 List of mailboxes load successfully
INFO 2022-04-28 18:40:02,133 basehttp 11923 139940152575744 "GET /api/mailbox/ HTTP/1.1" 200 7913
INFO 2022-04-28 18:40:02,551 autoreload 11923 139940230440768 /home/matt/PycharmProjects/mailAPI/BASE/urls.py changed, reloading.
INFO 2022-04-28 18:40:02,902 autoreload 12463 140698929231680 Watching for file changes with StatReloader
ERROR 2022-04-28 18:40:08,480 log 12463 140698851366656 Internal Server Error: /api/mailbox/aa6092de-2ad2-4946-a201-c2ec5fbcb686
Traceback (most recent call last):
  File "/home/matt/.local/lib/python3.8/site-packages/django/core/handlers/exception.py", line 47, in inner
    response = get_response(request)
  File "/home/matt/.local/lib/python3.8/site-packages/django/core/handlers/base.py", line 181, in _get_response
    response = wrapped_callback(request, *callback_args, **callback_kwargs)
  File "/home/matt/.local/lib/python3.8/site-packages/django/views/decorators/csrf.py", line 54, in wrapped_view
    return view_func(*args, **kwargs)
  File "/home/matt/.local/lib/python3.8/site-packages/django/views/generic/base.py", line 69, in view
    return self.dispatch(request, *args, **kwargs)
  File "/usr/local/lib/python3.8/dist-packages/rest_framework/views.py", line 509, in dispatch
    response = self.handle_exception(exc)
  File "/usr/local/lib/python3.8/dist-packages/rest_framework/views.py", line 469, in handle_exception
    self.raise_uncaught_exception(exc)
  File "/usr/local/lib/python3.8/dist-packages/rest_framework/views.py", line 480, in raise_uncaught_exception
    raise exc
  File "/usr/local/lib/python3.8/dist-packages/rest_framework/views.py", line 506, in dispatch
    response = handler(request, *args, **kwargs)
TypeError: get() got an unexpected keyword argument 'id'
ERROR 2022-04-28 18:40:08,481 basehttp 12463 140698851366656 "GET /api/mailbox/aa6092de-2ad2-4946-a201-c2ec5fbcb686 HTTP/1.1" 500 92292
ERROR 2022-04-28 18:40:36,965 log 12463 140698851366656 Internal Server Error: /api/mailbox/aa6092de-2ad2-4946-a201-c2ec5fbcb686
Traceback (most recent call last):
  File "/home/matt/.local/lib/python3.8/site-packages/django/core/handlers/exception.py", line 47, in inner
    response = get_response(request)
  File "/home/matt/.local/lib/python3.8/site-packages/django/core/handlers/base.py", line 181, in _get_response
    response = wrapped_callback(request, *callback_args, **callback_kwargs)
  File "/home/matt/.local/lib/python3.8/site-packages/django/views/decorators/csrf.py", line 54, in wrapped_view
    return view_func(*args, **kwargs)
  File "/home/matt/.local/lib/python3.8/site-packages/django/views/generic/base.py", line 69, in view
    return self.dispatch(request, *args, **kwargs)
  File "/usr/local/lib/python3.8/dist-packages/rest_framework/views.py", line 509, in dispatch
    response = self.handle_exception(exc)
  File "/usr/local/lib/python3.8/dist-packages/rest_framework/views.py", line 469, in handle_exception
    self.raise_uncaught_exception(exc)
  File "/usr/local/lib/python3.8/dist-packages/rest_framework/views.py", line 480, in raise_uncaught_exception
    raise exc
  File "/usr/local/lib/python3.8/dist-packages/rest_framework/views.py", line 506, in dispatch
    response = handler(request, *args, **kwargs)
TypeError: get() got an unexpected keyword argument 'id'
ERROR 2022-04-28 18:40:36,965 basehttp 12463 140698851366656 "GET /api/mailbox/aa6092de-2ad2-4946-a201-c2ec5fbcb686 HTTP/1.1" 500 92429
INFO 2022-04-28 18:40:37,725 autoreload 12463 140698929231680 /home/matt/PycharmProjects/mailAPI/BASE/views.py changed, reloading.
INFO 2022-04-28 18:40:38,008 autoreload 12498 140615667853120 Watching for file changes with StatReloader
INFO 2022-04-28 18:40:52,476 autoreload 12498 140615667853120 /home/matt/PycharmProjects/mailAPI/BASE/views.py changed, reloading.
INFO 2022-04-28 18:40:52,788 autoreload 12514 140699600930624 Watching for file changes with StatReloader
ERROR 2022-04-28 18:40:53,632 log 12514 140699523589888 Internal Server Error: /api/mailbox/aa6092de-2ad2-4946-a201-c2ec5fbcb686
Traceback (most recent call last):
  File "/home/matt/.local/lib/python3.8/site-packages/django/core/handlers/exception.py", line 47, in inner
    response = get_response(request)
  File "/home/matt/.local/lib/python3.8/site-packages/django/core/handlers/base.py", line 181, in _get_response
    response = wrapped_callback(request, *callback_args, **callback_kwargs)
  File "/home/matt/.local/lib/python3.8/site-packages/django/views/decorators/csrf.py", line 54, in wrapped_view
    return view_func(*args, **kwargs)
  File "/home/matt/.local/lib/python3.8/site-packages/django/views/generic/base.py", line 69, in view
    return self.dispatch(request, *args, **kwargs)
  File "/usr/local/lib/python3.8/dist-packages/rest_framework/views.py", line 509, in dispatch
    response = self.handle_exception(exc)
  File "/usr/local/lib/python3.8/dist-packages/rest_framework/views.py", line 469, in handle_exception
    self.raise_uncaught_exception(exc)
  File "/usr/local/lib/python3.8/dist-packages/rest_framework/views.py", line 480, in raise_uncaught_exception
    raise exc
  File "/usr/local/lib/python3.8/dist-packages/rest_framework/views.py", line 506, in dispatch
    response = handler(request, *args, **kwargs)
TypeError: get() got an unexpected keyword argument 'id'
ERROR 2022-04-28 18:40:53,632 basehttp 12514 140699523589888 "GET /api/mailbox/aa6092de-2ad2-4946-a201-c2ec5fbcb686 HTTP/1.1" 500 92429
INFO 2022-04-28 18:42:33,627 autoreload 12514 140699600930624 /home/matt/PycharmProjects/mailAPI/BASE/views.py changed, reloading.
INFO 2022-04-28 18:42:33,928 autoreload 12696 140301227308864 Watching for file changes with StatReloader
ERROR 2022-04-28 18:42:34,726 log 12696 140301079410432 Internal Server Error: /api/mailbox/aa6092de-2ad2-4946-a201-c2ec5fbcb686
Traceback (most recent call last):
  File "/home/matt/.local/lib/python3.8/site-packages/django/core/handlers/exception.py", line 47, in inner
    response = get_response(request)
  File "/home/matt/.local/lib/python3.8/site-packages/django/core/handlers/base.py", line 181, in _get_response
    response = wrapped_callback(request, *callback_args, **callback_kwargs)
  File "/home/matt/.local/lib/python3.8/site-packages/django/views/decorators/csrf.py", line 54, in wrapped_view
    return view_func(*args, **kwargs)
  File "/home/matt/.local/lib/python3.8/site-packages/django/views/generic/base.py", line 69, in view
    return self.dispatch(request, *args, **kwargs)
  File "/usr/local/lib/python3.8/dist-packages/rest_framework/views.py", line 509, in dispatch
    response = self.handle_exception(exc)
  File "/usr/local/lib/python3.8/dist-packages/rest_framework/views.py", line 469, in handle_exception
    self.raise_uncaught_exception(exc)
  File "/usr/local/lib/python3.8/dist-packages/rest_framework/views.py", line 480, in raise_uncaught_exception
    raise exc
  File "/usr/local/lib/python3.8/dist-packages/rest_framework/views.py", line 506, in dispatch
    response = handler(request, *args, **kwargs)
TypeError: get() got an unexpected keyword argument 'id'
ERROR 2022-04-28 18:42:34,727 basehttp 12696 140301079410432 "GET /api/mailbox/aa6092de-2ad2-4946-a201-c2ec5fbcb686 HTTP/1.1" 500 92429
ERROR 2022-04-28 18:42:37,200 log 12696 140301079410432 Internal Server Error: /api/mailbox/aa6092de-2ad2-4946-a201-c2ec5fbcb686
Traceback (most recent call last):
  File "/home/matt/.local/lib/python3.8/site-packages/django/core/handlers/exception.py", line 47, in inner
    response = get_response(request)
  File "/home/matt/.local/lib/python3.8/site-packages/django/core/handlers/base.py", line 181, in _get_response
    response = wrapped_callback(request, *callback_args, **callback_kwargs)
  File "/home/matt/.local/lib/python3.8/site-packages/django/views/decorators/csrf.py", line 54, in wrapped_view
    return view_func(*args, **kwargs)
  File "/home/matt/.local/lib/python3.8/site-packages/django/views/generic/base.py", line 69, in view
    return self.dispatch(request, *args, **kwargs)
  File "/usr/local/lib/python3.8/dist-packages/rest_framework/views.py", line 509, in dispatch
    response = self.handle_exception(exc)
  File "/usr/local/lib/python3.8/dist-packages/rest_framework/views.py", line 469, in handle_exception
    self.raise_uncaught_exception(exc)
  File "/usr/local/lib/python3.8/dist-packages/rest_framework/views.py", line 480, in raise_uncaught_exception
    raise exc
  File "/usr/local/lib/python3.8/dist-packages/rest_framework/views.py", line 506, in dispatch
    response = handler(request, *args, **kwargs)
TypeError: get() got an unexpected keyword argument 'id'
ERROR 2022-04-28 18:42:37,201 basehttp 12696 140301079410432 "GET /api/mailbox/aa6092de-2ad2-4946-a201-c2ec5fbcb686 HTTP/1.1" 500 92429
ERROR 2022-04-28 18:42:43,089 log 12696 140301079410432 Internal Server Error: /api/mailbox/aa6092de-2ad2-4946-a201-c2ec5fbcb686
Traceback (most recent call last):
  File "/home/matt/.local/lib/python3.8/site-packages/django/core/handlers/exception.py", line 47, in inner
    response = get_response(request)
  File "/home/matt/.local/lib/python3.8/site-packages/django/core/handlers/base.py", line 181, in _get_response
    response = wrapped_callback(request, *callback_args, **callback_kwargs)
  File "/home/matt/.local/lib/python3.8/site-packages/django/views/decorators/csrf.py", line 54, in wrapped_view
    return view_func(*args, **kwargs)
  File "/home/matt/.local/lib/python3.8/site-packages/django/views/generic/base.py", line 69, in view
    return self.dispatch(request, *args, **kwargs)
  File "/usr/local/lib/python3.8/dist-packages/rest_framework/views.py", line 509, in dispatch
    response = self.handle_exception(exc)
  File "/usr/local/lib/python3.8/dist-packages/rest_framework/views.py", line 469, in handle_exception
    self.raise_uncaught_exception(exc)
  File "/usr/local/lib/python3.8/dist-packages/rest_framework/views.py", line 480, in raise_uncaught_exception
    raise exc
  File "/usr/local/lib/python3.8/dist-packages/rest_framework/views.py", line 506, in dispatch
    response = handler(request, *args, **kwargs)
TypeError: get() got an unexpected keyword argument 'id'
ERROR 2022-04-28 18:42:43,089 basehttp 12696 140301079410432 "GET /api/mailbox/aa6092de-2ad2-4946-a201-c2ec5fbcb686 HTTP/1.1" 500 92429
INFO 2022-04-28 18:43:37,190 autoreload 12696 140301227308864 /home/matt/PycharmProjects/mailAPI/BASE/urls.py changed, reloading.
INFO 2022-04-28 18:43:37,516 autoreload 12844 140549896001344 Watching for file changes with StatReloader
ERROR 2022-04-28 18:43:40,619 log 12844 140549818136320 Internal Server Error: /api/mailbox/aa6092de-2ad2-4946-a201-c2ec5fbcb686
Traceback (most recent call last):
  File "/home/matt/.local/lib/python3.8/site-packages/django/core/handlers/exception.py", line 47, in inner
    response = get_response(request)
  File "/home/matt/.local/lib/python3.8/site-packages/django/core/handlers/base.py", line 181, in _get_response
    response = wrapped_callback(request, *callback_args, **callback_kwargs)
  File "/home/matt/.local/lib/python3.8/site-packages/django/views/decorators/csrf.py", line 54, in wrapped_view
    return view_func(*args, **kwargs)
  File "/home/matt/.local/lib/python3.8/site-packages/django/views/generic/base.py", line 69, in view
    return self.dispatch(request, *args, **kwargs)
  File "/usr/local/lib/python3.8/dist-packages/rest_framework/views.py", line 509, in dispatch
    response = self.handle_exception(exc)
  File "/usr/local/lib/python3.8/dist-packages/rest_framework/views.py", line 469, in handle_exception
    self.raise_uncaught_exception(exc)
  File "/usr/local/lib/python3.8/dist-packages/rest_framework/views.py", line 480, in raise_uncaught_exception
    raise exc
  File "/usr/local/lib/python3.8/dist-packages/rest_framework/views.py", line 506, in dispatch
    response = handler(request, *args, **kwargs)
  File "/home/matt/PycharmProjects/mailAPI/BASE/views.py", line 31, in get
    mailbox = Mailbox.objects.get(mailbox_id=mailbox_id)
  File "/home/matt/.local/lib/python3.8/site-packages/django/db/models/manager.py", line 85, in manager_method
    return getattr(self.get_queryset(), name)(*args, **kwargs)
  File "/home/matt/.local/lib/python3.8/site-packages/django/db/models/query.py", line 428, in get
    clone = self._chain() if self.query.combinator else self.filter(*args, **kwargs)
  File "/home/matt/.local/lib/python3.8/site-packages/django/db/models/query.py", line 974, in filter
    return self._filter_or_exclude(False, args, kwargs)
  File "/home/matt/.local/lib/python3.8/site-packages/django/db/models/query.py", line 992, in _filter_or_exclude
    clone._filter_or_exclude_inplace(negate, args, kwargs)
  File "/home/matt/.local/lib/python3.8/site-packages/django/db/models/query.py", line 999, in _filter_or_exclude_inplace
    self._query.add_q(Q(*args, **kwargs))
  File "/home/matt/.local/lib/python3.8/site-packages/django/db/models/sql/query.py", line 1375, in add_q
    clause, _ = self._add_q(q_object, self.used_aliases)
  File "/home/matt/.local/lib/python3.8/site-packages/django/db/models/sql/query.py", line 1396, in _add_q
    child_clause, needed_inner = self.build_filter(
  File "/home/matt/.local/lib/python3.8/site-packages/django/db/models/sql/query.py", line 1271, in build_filter
    lookups, parts, reffed_expression = self.solve_lookup_type(arg)
  File "/home/matt/.local/lib/python3.8/site-packages/django/db/models/sql/query.py", line 1099, in solve_lookup_type
    _, field, _, lookup_parts = self.names_to_path(lookup_splitted, self.get_meta())
  File "/home/matt/.local/lib/python3.8/site-packages/django/db/models/sql/query.py", line 1522, in names_to_path
    raise FieldError("Cannot resolve keyword '%s' into field. "
django.core.exceptions.FieldError: Cannot resolve keyword 'mailbox_id' into field. Choices are: date, email, email_from, host, id, is_active, last_update, login, password, port, use_ssl
ERROR 2022-04-28 18:43:40,620 basehttp 12844 140549818136320 "GET /api/mailbox/aa6092de-2ad2-4946-a201-c2ec5fbcb686 HTTP/1.1" 500 145187
INFO 2022-04-28 18:44:09,288 autoreload 12844 140549896001344 /home/matt/PycharmProjects/mailAPI/BASE/urls.py changed, reloading.
INFO 2022-04-28 18:44:09,578 autoreload 12894 140051559790400 Watching for file changes with StatReloader
ERROR 2022-04-28 18:44:10,890 log 12894 140051481925376 Internal Server Error: /api/mailbox/aa6092de-2ad2-4946-a201-c2ec5fbcb686
Traceback (most recent call last):
  File "/home/matt/.local/lib/python3.8/site-packages/django/core/handlers/exception.py", line 47, in inner
    response = get_response(request)
  File "/home/matt/.local/lib/python3.8/site-packages/django/core/handlers/base.py", line 181, in _get_response
    response = wrapped_callback(request, *callback_args, **callback_kwargs)
  File "/home/matt/.local/lib/python3.8/site-packages/django/views/decorators/csrf.py", line 54, in wrapped_view
    return view_func(*args, **kwargs)
  File "/home/matt/.local/lib/python3.8/site-packages/django/views/generic/base.py", line 69, in view
    return self.dispatch(request, *args, **kwargs)
  File "/usr/local/lib/python3.8/dist-packages/rest_framework/views.py", line 509, in dispatch
    response = self.handle_exception(exc)
  File "/usr/local/lib/python3.8/dist-packages/rest_framework/views.py", line 469, in handle_exception
    self.raise_uncaught_exception(exc)
  File "/usr/local/lib/python3.8/dist-packages/rest_framework/views.py", line 480, in raise_uncaught_exception
    raise exc
  File "/usr/local/lib/python3.8/dist-packages/rest_framework/views.py", line 506, in dispatch
    response = handler(request, *args, **kwargs)
TypeError: get() got an unexpected keyword argument 'id'
ERROR 2022-04-28 18:44:10,891 basehttp 12894 140051481925376 "GET /api/mailbox/aa6092de-2ad2-4946-a201-c2ec5fbcb686 HTTP/1.1" 500 92429
INFO 2022-04-28 18:44:44,409 autoreload 12894 140051559790400 /home/matt/PycharmProjects/mailAPI/BASE/views.py changed, reloading.
INFO 2022-04-28 18:44:44,690 autoreload 12930 140634976171840 Watching for file changes with StatReloader
ERROR 2022-04-28 18:45:10,898 log 12930 140634898306816 Internal Server Error: /api/mailbox/aa6092de-2ad2-4946-a201-c2ec5fbcb686
Traceback (most recent call last):
  File "/home/matt/.local/lib/python3.8/site-packages/django/core/handlers/exception.py", line 47, in inner
    response = get_response(request)
  File "/home/matt/.local/lib/python3.8/site-packages/django/core/handlers/base.py", line 181, in _get_response
    response = wrapped_callback(request, *callback_args, **callback_kwargs)
  File "/home/matt/.local/lib/python3.8/site-packages/django/views/decorators/csrf.py", line 54, in wrapped_view
    return view_func(*args, **kwargs)
  File "/home/matt/.local/lib/python3.8/site-packages/django/views/generic/base.py", line 69, in view
    return self.dispatch(request, *args, **kwargs)
  File "/usr/local/lib/python3.8/dist-packages/rest_framework/views.py", line 509, in dispatch
    response = self.handle_exception(exc)
  File "/usr/local/lib/python3.8/dist-packages/rest_framework/views.py", line 469, in handle_exception
    self.raise_uncaught_exception(exc)
  File "/usr/local/lib/python3.8/dist-packages/rest_framework/views.py", line 480, in raise_uncaught_exception
    raise exc
  File "/usr/local/lib/python3.8/dist-packages/rest_framework/views.py", line 506, in dispatch
    response = handler(request, *args, **kwargs)
TypeError: get() got an unexpected keyword argument 'id'
ERROR 2022-04-28 18:45:10,899 basehttp 12930 140634898306816 "GET /api/mailbox/aa6092de-2ad2-4946-a201-c2ec5fbcb686 HTTP/1.1" 500 92429
INFO 2022-04-28 18:45:24,549 autoreload 12930 140634976171840 /home/matt/PycharmProjects/mailAPI/BASE/views.py changed, reloading.
INFO 2022-04-28 18:45:24,861 autoreload 12984 140390321792832 Watching for file changes with StatReloader
ERROR 2022-04-28 18:45:25,727 log 12984 140390244452096 Internal Server Error: /api/mailbox/aa6092de-2ad2-4946-a201-c2ec5fbcb686
Traceback (most recent call last):
  File "/home/matt/.local/lib/python3.8/site-packages/django/core/handlers/exception.py", line 47, in inner
    response = get_response(request)
  File "/home/matt/.local/lib/python3.8/site-packages/django/core/handlers/base.py", line 181, in _get_response
    response = wrapped_callback(request, *callback_args, **callback_kwargs)
  File "/home/matt/.local/lib/python3.8/site-packages/django/views/decorators/csrf.py", line 54, in wrapped_view
    return view_func(*args, **kwargs)
  File "/home/matt/.local/lib/python3.8/site-packages/django/views/generic/base.py", line 69, in view
    return self.dispatch(request, *args, **kwargs)
  File "/usr/local/lib/python3.8/dist-packages/rest_framework/views.py", line 509, in dispatch
    response = self.handle_exception(exc)
  File "/usr/local/lib/python3.8/dist-packages/rest_framework/views.py", line 469, in handle_exception
    self.raise_uncaught_exception(exc)
  File "/usr/local/lib/python3.8/dist-packages/rest_framework/views.py", line 480, in raise_uncaught_exception
    raise exc
  File "/usr/local/lib/python3.8/dist-packages/rest_framework/views.py", line 506, in dispatch
    response = handler(request, *args, **kwargs)
TypeError: get() got an unexpected keyword argument 'id'
ERROR 2022-04-28 18:45:25,727 basehttp 12984 140390244452096 "GET /api/mailbox/aa6092de-2ad2-4946-a201-c2ec5fbcb686 HTTP/1.1" 500 92429
ERROR 2022-04-28 18:46:16,858 log 12984 140390244452096 Internal Server Error: /api/mailbox/aa6092de-2ad2-4946-a201-c2ec5fbcb686
Traceback (most recent call last):
  File "/home/matt/.local/lib/python3.8/site-packages/django/core/handlers/exception.py", line 47, in inner
    response = get_response(request)
  File "/home/matt/.local/lib/python3.8/site-packages/django/core/handlers/base.py", line 181, in _get_response
    response = wrapped_callback(request, *callback_args, **callback_kwargs)
  File "/home/matt/.local/lib/python3.8/site-packages/django/views/decorators/csrf.py", line 54, in wrapped_view
    return view_func(*args, **kwargs)
  File "/home/matt/.local/lib/python3.8/site-packages/django/views/generic/base.py", line 69, in view
    return self.dispatch(request, *args, **kwargs)
  File "/usr/local/lib/python3.8/dist-packages/rest_framework/views.py", line 509, in dispatch
    response = self.handle_exception(exc)
  File "/usr/local/lib/python3.8/dist-packages/rest_framework/views.py", line 469, in handle_exception
    self.raise_uncaught_exception(exc)
  File "/usr/local/lib/python3.8/dist-packages/rest_framework/views.py", line 480, in raise_uncaught_exception
    raise exc
  File "/usr/local/lib/python3.8/dist-packages/rest_framework/views.py", line 506, in dispatch
    response = handler(request, *args, **kwargs)
TypeError: get() got an unexpected keyword argument 'id'
ERROR 2022-04-28 18:46:16,858 basehttp 12984 140390244452096 "GET /api/mailbox/aa6092de-2ad2-4946-a201-c2ec5fbcb686 HTTP/1.1" 500 92429
INFO 2022-04-28 18:46:16,910 autoreload 12984 140390321792832 /home/matt/PycharmProjects/mailAPI/BASE/views.py changed, reloading.
INFO 2022-04-28 18:46:17,196 autoreload 13080 139646557701952 Watching for file changes with StatReloader
INFO 2022-04-28 18:46:19,080 views 13080 139646479836928 Single mailbox loaded successfully
INFO 2022-04-28 18:46:19,096 basehttp 13080 139646479836928 "GET /api/mailbox/aa6092de-2ad2-4946-a201-c2ec5fbcb686 HTTP/1.1" 200 5989
INFO 2022-04-28 18:46:53,050 autoreload 13080 139646557701952 /home/matt/PycharmProjects/mailAPI/BASE/views.py changed, reloading.
INFO 2022-04-28 18:46:53,365 autoreload 13128 140298177701696 Watching for file changes with StatReloader
INFO 2022-04-28 18:46:54,180 views 13128 140298100360960 Single mailbox loaded successfully
INFO 2022-04-28 18:46:54,198 basehttp 13128 140298100360960 "GET /api/mailbox/aa6092de-2ad2-4946-a201-c2ec5fbcb686 HTTP/1.1" 200 5989
INFO 2022-04-28 18:47:27,115 autoreload 13128 140298177701696 /home/matt/PycharmProjects/mailAPI/BASE/views.py changed, reloading.
INFO 2022-04-28 18:47:27,428 autoreload 13213 140483155797824 Watching for file changes with StatReloader
INFO 2022-04-28 18:49:16,343 autoreload 13213 140483155797824 /home/matt/PycharmProjects/mailAPI/BASE/views.py changed, reloading.
INFO 2022-04-28 18:49:16,648 autoreload 13334 140423493191488 Watching for file changes with StatReloader
INFO 2022-04-28 18:50:46,314 autoreload 13334 140423493191488 /home/matt/PycharmProjects/mailAPI/BASE/views.py changed, reloading.
INFO 2022-04-28 18:50:46,615 autoreload 13547 140633006671680 Watching for file changes with StatReloader
INFO 2022-04-28 18:50:49,755 views 13547 140632861619968 Single mailbox loaded successfully
INFO 2022-04-28 18:50:49,777 basehttp 13547 140632861619968 "GET /api/mailbox/aa6092de-2ad2-4946-a201-c2ec5fbcb686 HTTP/1.1" 200 7766
ERROR 2022-04-28 18:51:12,571 log 13547 140632861619968 Internal Server Error: /api/mailbox/aa6092de-2ad2-4946-a201-c2ec5fbcb686
Traceback (most recent call last):
  File "/home/matt/.local/lib/python3.8/site-packages/django/core/handlers/exception.py", line 47, in inner
    response = get_response(request)
  File "/home/matt/.local/lib/python3.8/site-packages/django/core/handlers/base.py", line 181, in _get_response
    response = wrapped_callback(request, *callback_args, **callback_kwargs)
  File "/home/matt/.local/lib/python3.8/site-packages/django/views/decorators/csrf.py", line 54, in wrapped_view
    return view_func(*args, **kwargs)
  File "/home/matt/.local/lib/python3.8/site-packages/django/views/generic/base.py", line 69, in view
    return self.dispatch(request, *args, **kwargs)
  File "/usr/local/lib/python3.8/dist-packages/rest_framework/views.py", line 509, in dispatch
    response = self.handle_exception(exc)
  File "/usr/local/lib/python3.8/dist-packages/rest_framework/views.py", line 469, in handle_exception
    self.raise_uncaught_exception(exc)
  File "/usr/local/lib/python3.8/dist-packages/rest_framework/views.py", line 480, in raise_uncaught_exception
    raise exc
  File "/usr/local/lib/python3.8/dist-packages/rest_framework/views.py", line 506, in dispatch
    response = handler(request, *args, **kwargs)
  File "/home/matt/PycharmProjects/mailAPI/BASE/views.py", line 39, in put
    if serializer.is_valid():
  File "/usr/local/lib/python3.8/dist-packages/rest_framework/serializers.py", line 220, in is_valid
    assert hasattr(self, 'initial_data'), (
AssertionError: Cannot call `.is_valid()` as no `data=` keyword argument was passed when instantiating the serializer instance.
ERROR 2022-04-28 18:51:12,572 basehttp 13547 140632861619968 "PUT /api/mailbox/aa6092de-2ad2-4946-a201-c2ec5fbcb686 HTTP/1.1" 500 102093
INFO 2022-04-28 18:52:04,187 autoreload 13547 140633006671680 /home/matt/PycharmProjects/mailAPI/BASE/views.py changed, reloading.
INFO 2022-04-28 18:52:04,489 autoreload 13745 140448576714560 Watching for file changes with StatReloader
INFO 2022-04-28 18:52:18,492 views 13745 140448498849536 Single mailbox loaded successfully
INFO 2022-04-28 18:52:18,513 basehttp 13745 140448498849536 "GET /api/mailbox/aa6092de-2ad2-4946-a201-c2ec5fbcb686 HTTP/1.1" 200 7766
INFO 2022-04-28 18:52:30,328 views 13745 140448498849536 POST successfully
INFO 2022-04-28 18:52:30,348 basehttp 13745 140448498849536 "PUT /api/mailbox/aa6092de-2ad2-4946-a201-c2ec5fbcb686 HTTP/1.1" 201 7775
INFO 2022-04-28 18:52:43,413 autoreload 13745 140448576714560 /home/matt/PycharmProjects/mailAPI/BASE/views.py changed, reloading.
INFO 2022-04-28 18:52:43,718 autoreload 13819 140020550711104 Watching for file changes with StatReloader
INFO 2022-04-28 18:58:23,190 autoreload 13819 140020550711104 /home/matt/PycharmProjects/mailAPI/BASE/views.py changed, reloading.
INFO 2022-04-28 18:58:23,497 autoreload 14014 139742759147328 Watching for file changes with StatReloader
INFO 2022-04-28 19:00:35,718 autoreload 14014 139742759147328 /home/matt/PycharmProjects/mailAPI/BASE/views.py changed, reloading.
INFO 2022-04-28 19:00:36,003 autoreload 14233 140459942442816 Watching for file changes with StatReloader
INFO 2022-04-28 19:00:37,556 views 14233 140459791873792 Single mailbox loaded successfully
INFO 2022-04-28 19:00:37,580 basehttp 14233 140459791873792 "GET /api/mailbox/aa6092de-2ad2-4946-a201-c2ec5fbcb686 HTTP/1.1" 200 7971
INFO 2022-04-28 19:00:59,047 views 14233 140459791873792 PATCH successfully
INFO 2022-04-28 19:00:59,058 basehttp 14233 140459791873792 "PATCH /api/mailbox/aa6092de-2ad2-4946-a201-c2ec5fbcb686 HTTP/1.1" 201 7980
INFO 2022-04-28 19:02:33,099 autoreload 14233 140459942442816 /home/matt/PycharmProjects/mailAPI/BASE/views.py changed, reloading.
INFO 2022-04-28 19:02:33,375 autoreload 14326 140396196849472 Watching for file changes with StatReloader
INFO 2022-04-28 19:03:14,202 autoreload 14326 140396196849472 /home/matt/PycharmProjects/mailAPI/BASE/views.py changed, reloading.
INFO 2022-04-28 19:03:14,510 autoreload 14350 140231929595712 Watching for file changes with StatReloader
INFO 2022-04-28 19:12:50,665 autoreload 14350 140231929595712 /home/matt/PycharmProjects/mailAPI/BASE/views.py changed, reloading.
INFO 2022-04-28 19:12:50,951 autoreload 15172 139871290746688 Watching for file changes with StatReloader
INFO 2022-04-28 19:15:19,499 autoreload 15172 139871290746688 /home/matt/PycharmProjects/mailAPI/BASE/views.py changed, reloading.
INFO 2022-04-28 19:15:19,833 autoreload 15307 140623757174592 Watching for file changes with StatReloader
INFO 2022-04-28 19:26:24,414 views 15307 140623604610816 Single mailbox loaded successfully
INFO 2022-04-28 19:26:24,436 basehttp 15307 140623604610816 "GET /api/mailbox/aa6092de-2ad2-4946-a201-c2ec5fbcb686 HTTP/1.1" 200 9050
INFO 2022-04-28 19:26:39,448 basehttp 15307 140623604610816 "GET /api/templates HTTP/1.1" 301 0
INFO 2022-04-28 19:26:39,467 views 15307 140623604610816 List of templates load successfully
ERROR 2022-04-28 19:26:39,502 log 15307 140623604610816 Internal Server Error: /api/templates/
Traceback (most recent call last):
  File "/usr/local/lib/python3.8/dist-packages/rest_framework/fields.py", line 457, in get_attribute
    return get_attribute(instance, self.source_attrs)
  File "/usr/local/lib/python3.8/dist-packages/rest_framework/fields.py", line 97, in get_attribute
    instance = getattr(instance, attr)
AttributeError: 'QuerySet' object has no attribute 'subject'

During handling of the above exception, another exception occurred:

Traceback (most recent call last):
  File "/home/matt/.local/lib/python3.8/site-packages/django/core/handlers/exception.py", line 47, in inner
    response = get_response(request)
  File "/home/matt/.local/lib/python3.8/site-packages/django/core/handlers/base.py", line 181, in _get_response
    response = wrapped_callback(request, *callback_args, **callback_kwargs)
  File "/home/matt/.local/lib/python3.8/site-packages/django/views/decorators/csrf.py", line 54, in wrapped_view
    return view_func(*args, **kwargs)
  File "/home/matt/.local/lib/python3.8/site-packages/django/views/generic/base.py", line 69, in view
    return self.dispatch(request, *args, **kwargs)
  File "/usr/local/lib/python3.8/dist-packages/rest_framework/views.py", line 509, in dispatch
    response = self.handle_exception(exc)
  File "/usr/local/lib/python3.8/dist-packages/rest_framework/views.py", line 469, in handle_exception
    self.raise_uncaught_exception(exc)
  File "/usr/local/lib/python3.8/dist-packages/rest_framework/views.py", line 480, in raise_uncaught_exception
    raise exc
  File "/usr/local/lib/python3.8/dist-packages/rest_framework/views.py", line 506, in dispatch
    response = handler(request, *args, **kwargs)
  File "/home/matt/PycharmProjects/mailAPI/BASE/views.py", line 70, in get
    return Response(serializers.data)
  File "/usr/local/lib/python3.8/dist-packages/rest_framework/serializers.py", line 555, in data
    ret = super().data
  File "/usr/local/lib/python3.8/dist-packages/rest_framework/serializers.py", line 253, in data
    self._data = self.to_representation(self.instance)
  File "/usr/local/lib/python3.8/dist-packages/rest_framework/serializers.py", line 509, in to_representation
    attribute = field.get_attribute(instance)
  File "/usr/local/lib/python3.8/dist-packages/rest_framework/fields.py", line 490, in get_attribute
    raise type(exc)(msg)
AttributeError: Got AttributeError when attempting to get a value for field `subject` on serializer `TemplateSerializer`.
The serializer field might be named incorrectly and not match any attribute or key on the `QuerySet` instance.
Original exception text was: 'QuerySet' object has no attribute 'subject'.
ERROR 2022-04-28 19:26:39,503 basehttp 15307 140623604610816 "GET /api/templates/ HTTP/1.1" 500 122721
INFO 2022-04-28 19:27:20,604 views 15307 140623604610816 List of templates load successfully
ERROR 2022-04-28 19:27:20,640 log 15307 140623604610816 Internal Server Error: /api/templates/
Traceback (most recent call last):
  File "/usr/local/lib/python3.8/dist-packages/rest_framework/fields.py", line 457, in get_attribute
    return get_attribute(instance, self.source_attrs)
  File "/usr/local/lib/python3.8/dist-packages/rest_framework/fields.py", line 97, in get_attribute
    instance = getattr(instance, attr)
AttributeError: 'QuerySet' object has no attribute 'subject'

During handling of the above exception, another exception occurred:

Traceback (most recent call last):
  File "/home/matt/.local/lib/python3.8/site-packages/django/core/handlers/exception.py", line 47, in inner
    response = get_response(request)
  File "/home/matt/.local/lib/python3.8/site-packages/django/core/handlers/base.py", line 181, in _get_response
    response = wrapped_callback(request, *callback_args, **callback_kwargs)
  File "/home/matt/.local/lib/python3.8/site-packages/django/views/decorators/csrf.py", line 54, in wrapped_view
    return view_func(*args, **kwargs)
  File "/home/matt/.local/lib/python3.8/site-packages/django/views/generic/base.py", line 69, in view
    return self.dispatch(request, *args, **kwargs)
  File "/usr/local/lib/python3.8/dist-packages/rest_framework/views.py", line 509, in dispatch
    response = self.handle_exception(exc)
  File "/usr/local/lib/python3.8/dist-packages/rest_framework/views.py", line 469, in handle_exception
    self.raise_uncaught_exception(exc)
  File "/usr/local/lib/python3.8/dist-packages/rest_framework/views.py", line 480, in raise_uncaught_exception
    raise exc
  File "/usr/local/lib/python3.8/dist-packages/rest_framework/views.py", line 506, in dispatch
    response = handler(request, *args, **kwargs)
  File "/home/matt/PycharmProjects/mailAPI/BASE/views.py", line 70, in get
    return Response(serializers.data)
  File "/usr/local/lib/python3.8/dist-packages/rest_framework/serializers.py", line 555, in data
    ret = super().data
  File "/usr/local/lib/python3.8/dist-packages/rest_framework/serializers.py", line 253, in data
    self._data = self.to_representation(self.instance)
  File "/usr/local/lib/python3.8/dist-packages/rest_framework/serializers.py", line 509, in to_representation
    attribute = field.get_attribute(instance)
  File "/usr/local/lib/python3.8/dist-packages/rest_framework/fields.py", line 490, in get_attribute
    raise type(exc)(msg)
AttributeError: Got AttributeError when attempting to get a value for field `subject` on serializer `TemplateSerializer`.
The serializer field might be named incorrectly and not match any attribute or key on the `QuerySet` instance.
Original exception text was: 'QuerySet' object has no attribute 'subject'.
ERROR 2022-04-28 19:27:20,641 basehttp 15307 140623604610816 "GET /api/templates/ HTTP/1.1" 500 122858
INFO 2022-04-28 19:27:42,837 autoreload 15307 140623757174592 /home/matt/PycharmProjects/mailAPI/BASE/views.py changed, reloading.
INFO 2022-04-28 19:27:43,158 autoreload 16107 140220495431488 Watching for file changes with StatReloader
INFO 2022-04-28 19:27:43,969 views 16107 140220347447040 List of templates load successfully
ERROR 2022-04-28 19:27:44,008 log 16107 140220347447040 Internal Server Error: /api/templates/
Traceback (most recent call last):
  File "/home/matt/.local/lib/python3.8/site-packages/django/core/handlers/exception.py", line 47, in inner
    response = get_response(request)
  File "/home/matt/.local/lib/python3.8/site-packages/django/core/handlers/base.py", line 204, in _get_response
    response = response.render()
  File "/home/matt/.local/lib/python3.8/site-packages/django/template/response.py", line 105, in render
    self.content = self.rendered_content
  File "/usr/local/lib/python3.8/dist-packages/rest_framework/response.py", line 70, in rendered_content
    ret = renderer.render(self.data, accepted_media_type, context)
  File "/usr/local/lib/python3.8/dist-packages/rest_framework/renderers.py", line 724, in render
    context = self.get_context(data, accepted_media_type, renderer_context)
  File "/usr/local/lib/python3.8/dist-packages/rest_framework/renderers.py", line 680, in get_context
    'content': self.get_content(renderer, data, accepted_media_type, renderer_context),
  File "/usr/local/lib/python3.8/dist-packages/rest_framework/renderers.py", line 413, in get_content
    content = renderer.render(data, accepted_media_type, renderer_context)
  File "/usr/local/lib/python3.8/dist-packages/rest_framework/renderers.py", line 100, in render
    ret = json.dumps(
  File "/usr/local/lib/python3.8/dist-packages/rest_framework/utils/json.py", line 25, in dumps
    return json.dumps(*args, **kwargs)
  File "/usr/lib/python3.8/json/__init__.py", line 234, in dumps
    return cls(
  File "/usr/lib/python3.8/json/encoder.py", line 201, in encode
    chunks = list(chunks)
  File "/usr/lib/python3.8/json/encoder.py", line 429, in _iterencode
    yield from _iterencode_list(o, _current_indent_level)
  File "/usr/lib/python3.8/json/encoder.py", line 325, in _iterencode_list
    yield from chunks
  File "/usr/lib/python3.8/json/encoder.py", line 405, in _iterencode_dict
    yield from chunks
  File "/usr/lib/python3.8/json/encoder.py", line 438, in _iterencode
    o = _default(o)
  File "/usr/local/lib/python3.8/dist-packages/rest_framework/utils/encoders.py", line 67, in default
    return super().default(obj)
  File "/usr/lib/python3.8/json/encoder.py", line 179, in default
    raise TypeError(f'Object of type {o.__class__.__name__} '
TypeError: Object of type type is not JSON serializable
ERROR 2022-04-28 19:27:44,009 basehttp 16107 140220347447040 "GET /api/templates/ HTTP/1.1" 500 162705
INFO 2022-04-28 19:28:20,984 autoreload 16107 140220495431488 /home/matt/PycharmProjects/mailAPI/BASE/views.py changed, reloading.
INFO 2022-04-28 19:28:21,307 autoreload 16178 139630074865472 Watching for file changes with StatReloader
INFO 2022-04-28 19:28:22,117 views 16178 139629923661568 List of templates load successfully
ERROR 2022-04-28 19:28:22,150 log 16178 139629923661568 Internal Server Error: /api/templates/
Traceback (most recent call last):
  File "/home/matt/.local/lib/python3.8/site-packages/django/core/handlers/exception.py", line 47, in inner
    response = get_response(request)
  File "/home/matt/.local/lib/python3.8/site-packages/django/core/handlers/base.py", line 204, in _get_response
    response = response.render()
  File "/home/matt/.local/lib/python3.8/site-packages/django/template/response.py", line 105, in render
    self.content = self.rendered_content
  File "/usr/local/lib/python3.8/dist-packages/rest_framework/response.py", line 70, in rendered_content
    ret = renderer.render(self.data, accepted_media_type, context)
  File "/usr/local/lib/python3.8/dist-packages/rest_framework/renderers.py", line 724, in render
    context = self.get_context(data, accepted_media_type, renderer_context)
  File "/usr/local/lib/python3.8/dist-packages/rest_framework/renderers.py", line 680, in get_context
    'content': self.get_content(renderer, data, accepted_media_type, renderer_context),
  File "/usr/local/lib/python3.8/dist-packages/rest_framework/renderers.py", line 413, in get_content
    content = renderer.render(data, accepted_media_type, renderer_context)
  File "/usr/local/lib/python3.8/dist-packages/rest_framework/renderers.py", line 100, in render
    ret = json.dumps(
  File "/usr/local/lib/python3.8/dist-packages/rest_framework/utils/json.py", line 25, in dumps
    return json.dumps(*args, **kwargs)
  File "/usr/lib/python3.8/json/__init__.py", line 234, in dumps
    return cls(
  File "/usr/lib/python3.8/json/encoder.py", line 201, in encode
    chunks = list(chunks)
  File "/usr/lib/python3.8/json/encoder.py", line 429, in _iterencode
    yield from _iterencode_list(o, _current_indent_level)
  File "/usr/lib/python3.8/json/encoder.py", line 325, in _iterencode_list
    yield from chunks
  File "/usr/lib/python3.8/json/encoder.py", line 405, in _iterencode_dict
    yield from chunks
  File "/usr/lib/python3.8/json/encoder.py", line 438, in _iterencode
    o = _default(o)
  File "/usr/local/lib/python3.8/dist-packages/rest_framework/utils/encoders.py", line 67, in default
    return super().default(obj)
  File "/usr/lib/python3.8/json/encoder.py", line 179, in default
    raise TypeError(f'Object of type {o.__class__.__name__} '
TypeError: Object of type type is not JSON serializable
ERROR 2022-04-28 19:28:22,151 basehttp 16178 139629923661568 "GET /api/templates/ HTTP/1.1" 500 162705
INFO 2022-04-28 19:29:58,106 autoreload 16178 139630074865472 /home/matt/PycharmProjects/mailAPI/BASE/views.py changed, reloading.
INFO 2022-04-28 19:29:58,406 autoreload 16610 140132033328960 Watching for file changes with StatReloader
INFO 2022-04-28 19:29:59,489 views 16610 140131955988224 List of templates load successfully
ERROR 2022-04-28 19:29:59,524 log 16610 140131955988224 Internal Server Error: /api/templates/
Traceback (most recent call last):
  File "/home/matt/.local/lib/python3.8/site-packages/django/core/handlers/exception.py", line 47, in inner
    response = get_response(request)
  File "/home/matt/.local/lib/python3.8/site-packages/django/core/handlers/base.py", line 204, in _get_response
    response = response.render()
  File "/home/matt/.local/lib/python3.8/site-packages/django/template/response.py", line 105, in render
    self.content = self.rendered_content
  File "/usr/local/lib/python3.8/dist-packages/rest_framework/response.py", line 70, in rendered_content
    ret = renderer.render(self.data, accepted_media_type, context)
  File "/usr/local/lib/python3.8/dist-packages/rest_framework/renderers.py", line 724, in render
    context = self.get_context(data, accepted_media_type, renderer_context)
  File "/usr/local/lib/python3.8/dist-packages/rest_framework/renderers.py", line 680, in get_context
    'content': self.get_content(renderer, data, accepted_media_type, renderer_context),
  File "/usr/local/lib/python3.8/dist-packages/rest_framework/renderers.py", line 413, in get_content
    content = renderer.render(data, accepted_media_type, renderer_context)
  File "/usr/local/lib/python3.8/dist-packages/rest_framework/renderers.py", line 100, in render
    ret = json.dumps(
  File "/usr/local/lib/python3.8/dist-packages/rest_framework/utils/json.py", line 25, in dumps
    return json.dumps(*args, **kwargs)
  File "/usr/lib/python3.8/json/__init__.py", line 234, in dumps
    return cls(
  File "/usr/lib/python3.8/json/encoder.py", line 201, in encode
    chunks = list(chunks)
  File "/usr/lib/python3.8/json/encoder.py", line 429, in _iterencode
    yield from _iterencode_list(o, _current_indent_level)
  File "/usr/lib/python3.8/json/encoder.py", line 325, in _iterencode_list
    yield from chunks
  File "/usr/lib/python3.8/json/encoder.py", line 405, in _iterencode_dict
    yield from chunks
  File "/usr/lib/python3.8/json/encoder.py", line 438, in _iterencode
    o = _default(o)
  File "/usr/local/lib/python3.8/dist-packages/rest_framework/utils/encoders.py", line 67, in default
    return super().default(obj)
  File "/usr/lib/python3.8/json/encoder.py", line 179, in default
    raise TypeError(f'Object of type {o.__class__.__name__} '
TypeError: Object of type type is not JSON serializable
ERROR 2022-04-28 19:29:59,525 basehttp 16610 140131955988224 "GET /api/templates/ HTTP/1.1" 500 162705
INFO 2022-04-28 19:30:36,243 autoreload 16610 140132033328960 /home/matt/PycharmProjects/mailAPI/BASE/views.py changed, reloading.
INFO 2022-04-28 19:30:36,559 autoreload 16642 139899250788160 Watching for file changes with StatReloader
INFO 2022-04-28 19:31:27,587 autoreload 16642 139899250788160 /home/matt/PycharmProjects/mailAPI/BASE/views.py changed, reloading.
INFO 2022-04-28 19:31:27,881 autoreload 16683 140188873484096 Watching for file changes with StatReloader
INFO 2022-04-28 19:38:10,433 views 16683 140188795619072 List of templates load successfully
ERROR 2022-04-28 19:38:10,472 log 16683 140188795619072 Internal Server Error: /api/templates/
Traceback (most recent call last):
  File "/home/matt/.local/lib/python3.8/site-packages/django/core/handlers/exception.py", line 47, in inner
    response = get_response(request)
  File "/home/matt/.local/lib/python3.8/site-packages/django/core/handlers/base.py", line 204, in _get_response
    response = response.render()
  File "/home/matt/.local/lib/python3.8/site-packages/django/template/response.py", line 105, in render
    self.content = self.rendered_content
  File "/usr/local/lib/python3.8/dist-packages/rest_framework/response.py", line 70, in rendered_content
    ret = renderer.render(self.data, accepted_media_type, context)
  File "/usr/local/lib/python3.8/dist-packages/rest_framework/renderers.py", line 724, in render
    context = self.get_context(data, accepted_media_type, renderer_context)
  File "/usr/local/lib/python3.8/dist-packages/rest_framework/renderers.py", line 680, in get_context
    'content': self.get_content(renderer, data, accepted_media_type, renderer_context),
  File "/usr/local/lib/python3.8/dist-packages/rest_framework/renderers.py", line 413, in get_content
    content = renderer.render(data, accepted_media_type, renderer_context)
  File "/usr/local/lib/python3.8/dist-packages/rest_framework/renderers.py", line 100, in render
    ret = json.dumps(
  File "/usr/local/lib/python3.8/dist-packages/rest_framework/utils/json.py", line 25, in dumps
    return json.dumps(*args, **kwargs)
  File "/usr/lib/python3.8/json/__init__.py", line 234, in dumps
    return cls(
  File "/usr/lib/python3.8/json/encoder.py", line 201, in encode
    chunks = list(chunks)
  File "/usr/lib/python3.8/json/encoder.py", line 429, in _iterencode
    yield from _iterencode_list(o, _current_indent_level)
  File "/usr/lib/python3.8/json/encoder.py", line 325, in _iterencode_list
    yield from chunks
  File "/usr/lib/python3.8/json/encoder.py", line 405, in _iterencode_dict
    yield from chunks
  File "/usr/lib/python3.8/json/encoder.py", line 438, in _iterencode
    o = _default(o)
  File "/usr/local/lib/python3.8/dist-packages/rest_framework/utils/encoders.py", line 67, in default
    return super().default(obj)
  File "/usr/lib/python3.8/json/encoder.py", line 179, in default
    raise TypeError(f'Object of type {o.__class__.__name__} '
TypeError: Object of type type is not JSON serializable
ERROR 2022-04-28 19:38:10,473 basehttp 16683 140188795619072 "GET /api/templates/ HTTP/1.1" 500 162705
INFO 2022-04-28 19:38:10,565 autoreload 16683 140188873484096 /home/matt/PycharmProjects/mailAPI/BASE/views.py changed, reloading.
INFO 2022-04-28 19:38:10,852 autoreload 17373 140176465274688 Watching for file changes with StatReloader
INFO 2022-04-28 19:38:52,712 autoreload 17373 140176465274688 /home/matt/PycharmProjects/mailAPI/BASE/views.py changed, reloading.
INFO 2022-04-28 19:38:52,986 autoreload 17410 139731628455744 Watching for file changes with StatReloader
INFO 2022-04-28 19:41:10,366 autoreload 17410 139731628455744 /home/matt/PycharmProjects/mailAPI/BASE/serializers.py changed, reloading.
INFO 2022-04-28 19:41:10,654 autoreload 17638 139831116453696 Watching for file changes with StatReloader
INFO 2022-04-28 19:42:24,057 autoreload 17638 139831116453696 /home/matt/PycharmProjects/mailAPI/BASE/models.py changed, reloading.
INFO 2022-04-28 19:42:24,380 autoreload 17792 140017129371456 Watching for file changes with StatReloader
INFO 2022-05-03 17:43:22,243 autoreload 8025 140095296386880 Watching for file changes with StatReloader
WARNING 2022-05-03 17:43:24,189 log 8025 140095218521856 Not Found: /
WARNING 2022-05-03 17:43:24,190 basehttp 8025 140095218521856 "GET / HTTP/1.1" 404 2614
WARNING 2022-05-03 17:43:24,911 log 8025 140095218521856 Not Found: /favicon.ico
WARNING 2022-05-03 17:43:24,912 basehttp 8025 140095218521856 "GET /favicon.ico HTTP/1.1" 404 2665
INFO 2022-05-03 17:43:41,788 basehttp 8025 140095218521856 "GET /api/mailbox HTTP/1.1" 301 0
INFO 2022-05-03 17:43:41,809 views 8025 140095218521856 List of mailboxes load successfully
INFO 2022-05-03 17:43:41,832 basehttp 8025 140095218521856 "GET /api/mailbox/ HTTP/1.1" 200 7919
INFO 2022-05-03 17:43:41,864 basehttp 8025 140095210129152 "GET /static/rest_framework/css/bootstrap-tweaks.css HTTP/1.1" 200 3385
INFO 2022-05-03 17:43:41,865 basehttp 8025 140095200425728 "GET /static/rest_framework/css/prettify.css HTTP/1.1" 200 817
INFO 2022-05-03 17:43:41,867 basehttp 8025 140094988089088 "GET /static/rest_framework/css/default.css HTTP/1.1" 200 1152
INFO 2022-05-03 17:43:41,868 basehttp 8025 140094971303680 "GET /static/rest_framework/js/ajax-form.js HTTP/1.1" 200 3597
INFO 2022-05-03 17:43:41,870 basehttp 8025 140095218521856 "GET /static/rest_framework/css/bootstrap.min.css HTTP/1.1" 200 121457
INFO 2022-05-03 17:43:41,871 basehttp 8025 140094979696384 "GET /static/rest_framework/js/jquery-3.5.1.min.js HTTP/1.1" 200 89476
INFO 2022-05-03 17:43:41,878 basehttp 8025 140094971303680 "GET /static/rest_framework/js/csrf.js HTTP/1.1" 200 1719
INFO 2022-05-03 17:43:41,879 basehttp 8025 140095200425728 "GET /static/rest_framework/js/default.js HTTP/1.1" 200 1268
INFO 2022-05-03 17:43:41,879 basehttp 8025 140095210129152 "GET /static/rest_framework/js/prettify-min.js HTTP/1.1" 200 13632
INFO 2022-05-03 17:43:41,881 basehttp 8025 140094988089088 "GET /static/rest_framework/js/bootstrap.min.js HTTP/1.1" 200 39680
INFO 2022-05-03 17:43:45,264 basehttp 8025 140094988089088 "GET /static/rest_framework/img/grid.png HTTP/1.1" 200 1458
INFO 2022-05-03 17:43:51,514 views 8025 140094988089088 List of templates load successfully
INFO 2022-05-03 17:43:51,528 basehttp 8025 140094988089088 "GET /api/templates/ HTTP/1.1" 200 5693
INFO 2022-05-03 17:45:37,718 autoreload 8025 140095296386880 /home/matt/PycharmProjects/mailAPI/BASE/views.py changed, reloading.
INFO 2022-05-03 17:45:38,016 autoreload 8324 140545061209920 Watching for file changes with StatReloader
INFO 2022-05-03 17:45:39,283 views 8324 140544983869184 List of templates load successfully
INFO 2022-05-03 17:45:39,316 basehttp 8324 140544983869184 "GET /api/templates/ HTTP/1.1" 200 8688
ERROR 2022-05-03 17:46:24,588 log 8324 140544983869184 Internal Server Error: /api/templates/
Traceback (most recent call last):
  File "/home/matt/.local/lib/python3.8/site-packages/django/core/handlers/exception.py", line 47, in inner
    response = get_response(request)
  File "/home/matt/.local/lib/python3.8/site-packages/django/core/handlers/base.py", line 181, in _get_response
    response = wrapped_callback(request, *callback_args, **callback_kwargs)
  File "/home/matt/.local/lib/python3.8/site-packages/django/views/decorators/csrf.py", line 54, in wrapped_view
    return view_func(*args, **kwargs)
  File "/home/matt/.local/lib/python3.8/site-packages/django/views/generic/base.py", line 69, in view
    return self.dispatch(request, *args, **kwargs)
  File "/usr/local/lib/python3.8/dist-packages/rest_framework/views.py", line 509, in dispatch
    response = self.handle_exception(exc)
  File "/usr/local/lib/python3.8/dist-packages/rest_framework/views.py", line 469, in handle_exception
    self.raise_uncaught_exception(exc)
  File "/usr/local/lib/python3.8/dist-packages/rest_framework/views.py", line 480, in raise_uncaught_exception
    raise exc
  File "/usr/local/lib/python3.8/dist-packages/rest_framework/views.py", line 506, in dispatch
    response = handler(request, *args, **kwargs)
TypeError: put() missing 1 required positional argument: 'template_id'
ERROR 2022-05-03 17:46:24,589 basehttp 8324 140544983869184 "PUT /api/templates/ HTTP/1.1" 500 91682
INFO 2022-05-03 17:46:56,594 autoreload 8324 140545061209920 /home/matt/PycharmProjects/mailAPI/BASE/urls.py changed, reloading.
INFO 2022-05-03 17:46:56,941 autoreload 8422 140102722594624 Watching for file changes with StatReloader
INFO 2022-05-03 17:47:00,453 views 8422 140102571390720 List of mailboxes load successfully
INFO 2022-05-03 17:47:00,477 basehttp 8422 140102571390720 "GET /api/mailbox/ HTTP/1.1" 200 7919
INFO 2022-05-03 17:47:04,509 views 8422 140102571390720 List of templates load successfully
INFO 2022-05-03 17:47:04,523 basehttp 8422 140102571390720 "GET /api/templates/ HTTP/1.1" 200 8688
INFO 2022-05-03 17:47:24,585 views 8422 140102571390720 List of templates load successfully
INFO 2022-05-03 17:47:24,600 basehttp 8422 140102571390720 "GET /api/templates/ HTTP/1.1" 200 8688
INFO 2022-05-03 17:47:24,605 autoreload 8422 140102722594624 /home/matt/PycharmProjects/mailAPI/BASE/serializers.py changed, reloading.
INFO 2022-05-03 17:47:24,935 autoreload 8457 139806916327232 Watching for file changes with StatReloader
